Workbook

Sheet Morocco Prices
N1: Soufiane
B2: PRODUCT / SPECIFICATIONS | C2: FRANÇAIS | D2: PICTURE | E2: UNIT | F2: QUANTITY | G2: PRICE IN TURKEY (without kdv) + LOCAL TRANSP 'USD' | H2: KDV POSSIBILITY | I2: SHIPMENT*40HC* KONYA-TANGER | J2: COSTUMES (TURKEY) | L2: PRICE IN MOROCCO AZUR (without TVA) 'DH' | M2: PRICE IN MOROCCO ECO (without TVA) 'DH' | O2: PRICE IN MOROCCO AZUR | Q2: PRICE IN MOROCCO (-) | R2: made in morocco
A3: MECHANICAL PARTS
A4: CABINS | B4: CABIN ( 6 PERSONS. STAINLESS STEEL + PVC FLOOR ) + PACKING + ARCADE | C4: CABINE STANDARD INOX 1200/1100 + EMBALLAGE | E4: SET | F4: 1 | G4: 1475 | H4: NO | I4: 1400 | J4: 155 | L4: 18500 | M4: 15500 | O4: 0 | Q4: 16000 | R4: 12000
B5: CABIN STANDARD | C5: CABINE INOX 1200/1100 + EMBALLAGE | G5: 1000 | O5: 0
B6: CABIN PERSONILEZD | C6: CABINE INOX 1200/1100 + EMBALLAGE | G6: 1400 | O6: 0 | Q6: 8500 | R6: 6000
B7: CABIN FRAME + ROPE ATTACHEMNT + ROPE CONNECTORS + CONTRE POIDS | C7: ARCADE CABINE /DEG 1200 + ARCADE CONTRE-POIDS + TIRANDS + COULISSEAUX | G7: 450 | H7: NO | L7: 7700 | M7: 7800 | N7: HURAS BRAND | O7: 8500 | P7: ALYANS BRAND | Q7: 7500
A8: DOORS | B8: CABIN DOOR (DEAS) STAINLESS STEEL 70/80/90 CM | C8: PORTES CABINE / OPERATEUR *DEAS* INOX | E8: Pc | F8: 1 | G8: 330 | H8: NO | K8: HURAS BRAND | L8: 8500 | M8: 7800 | O8: 4600 | Q8: 4100
B9: LANDING DOOR (DEAS) STAINLESS STEEL 70/80/90 CM | C9: PORTES PALIERE AUTOMATIQUE INOX | E9: Pc | F9: 1 | G9: 225 | H9: NO | L9: 4600 | M9: 4700 | O9: 3500 | Q9: 3100
B10: LANDING DOOR (DEAS) RAL PAINTED 70/80/90 CM | C10: PORTES PALIERE AUTOMATIQUE PEINTURE EPOXY | E10: Pc | F10: 1 | G10: 185 | H10: NO | L10: 3500 | M10: 2900 | O10: 0 | Q10: 2600
A11: MANUEL DOORS+PARTS | B11: MANUEL DOOR RAL PAINTED 70/80/90 | C11: SEMI AUTOMATIC PORTES 70/80/90 | E11: Pc | F11: 1 | G11: 110 | H11: NO | L11: 0 | M11: 2500 | O11: 0 | Q11: 0
B12: MANUEL DOOR LOCK | C12: SERRURE (DOOR LOCK) | E12: Pc | F12: 1 | G12: 18 | H12: NO | L12: 0 | M12: 600 | O12: 1200 | Q12: 1200
B13: MANUEL DOOR GAM | C13: CAME DC 220V / 60V | E13: Pc | F13: 1 | G13: 44 | H13: NO | L13: 0 | M13: 1000 | O13: 0 | Q13: 0
B14: Door Shock Absorber | C14: DICTATOR | E14: Pc | F14: 1 | G14: 6.8 | H14: NO | L14: 0 | M14: 260 | O14: 19800 | Q14: 19000
A15: MOTOR | B15: MOTOR AKIŞ VVVF MF1 PROE 5.5KW 400KG/630KG +ENCODER | C15: Moteur AKIS VVVF 400KG/630KG +ENCODEUR | E15: Pc | F15: 1 | G15: 752 | H15: yes | L15: 0 | M15: 0 | O15: 0 | Q15: 0
B16: MOTOR AKIŞ VVVF MF1 PROE 7.5KW 500KG/800KG +ENCODER | C16: Moteur AKIS VVVF 500KG/800KG +ENCODEUR | E16: Pc | F16: 1 | G16: 762 | H16: yes | L16: 0 | M16: 0 | O16: 0 | Q16: 19500
B17: MOTOR AKIŞ MUGEN M2 SERİSİ GEARBOX 2 SPEED 480 KG | C17: Moteur AKIS 2 VITESSE 480KG | E17: Pc | F17: 1 | G17: 975 | H17: yes | L17: 0 | M17: 0 | O17: 0 | Q17: 0
B18: MOTOR AKIŞ MUGEN M2 SERİSİ GEARBOX 2 SPEED 720 KG | C18: Moteur AKIS 2 VITESSE 720KG | E18: Pc | F18: 1 | G18: 1070 | H18: yes | L18: 0 | M18: 0 | O18: 0 | Q18: 14
A19: RAILS/ CONSOLS/ BOLTS | B19: CONSOL 5*7cm | C19: CLASSIC BRACKET 60X60 patate | E19: Pc | F19: 1 | G19: 0.6 | H19: NO | L19: 25 | M19: 22 | O19: 0 | Q19: 16
B20: CONSOL 5*10cm | C20: CLASSIC BRACKET 60X80 | E20: Pc | F20: 1 | G20: 0.9 | H20: NO | L20: 31 | M20: 28 | O20: 9 | Q20: 15
B21: RAIL CLIPS 50 | C21: CROMPO 50 | E21: Pc | F21: 1 | G21: 0.28 | H21: NO | L21: 6.5 | M21: 13 | O21: 7
B22: RAIL CLIPS 70 | C22: CROMPO 70 | E22: Pc | F22: 1 | G22: 0.37 | H22: NO | L22: 7.5 | O22: 0 | Q22: 2.3
B23: M8*30 BOLT | C23: BOULON 8/30 | E23: Pc | F23: 1 | G23: 0.07 | H23: YES | L23: 0 | M23: 1.5 | O23: 0 | Q23: 3.2
B24: M12*40 BOLT | C24: BOULON 12/30 COMPLET | E24: Pc | F24: 1 | G24: 0.2 | H24: YES | L24: 0 | M24: 2.5 | O24: 0 | Q24: 5
B25: M14*70 BOLT | C25: BOULON 14/70 | E25: Pc | F25: 1 | G25: 0.3 | H25: YES | L25: 0 | M25: 0 | O25: 0 | Q25: 6
B26: WEDGE ANCHOR M12*110 | C26: CHEVEILLE 12/100 | E26: Pc | F26: 1 | G26: 0.21 | H26: NO | L26: 5.8 | M26: 6 | O26: 0 | Q26: 1050
B27: RAIL 50*50*5mm + FİSH PLATE (5M) | C27: GUIDE RAIL 50 | E27: SET | F27: 1 | G27: 16.4 | H27: NO | L27: 400 | M27: 400 | O27: 0
B28: RAIL 70*65*9mm + FİSH PLATE (5M) | C28: GUIDE RAIL 70 | G28: 32.6 | L28: 800 | M28: 800
A29: ROPES | B29: ROPE 10 MM | C29: Cable traction (10) | E29: M | F29: 1 | G29: 0.92 | H29: YES | L29: 18 | M29: 22 | O29: 0 | Q29: 18 | R29: Cable traction (10mm)
B30: ROPE 6 MM | C30: cable regulateur | E30: M | F30: 1 | G30: 0.28 | H30: YES | L30: 8 | M30: 10 | O30: 0 | Q30: 8 | R30: cable regulateur (6mm)
B31: ROPE ATTACHMENT 10MM | C31: Tirands 10MM | E31: Pc | F31: 1 | G31: 2.15 | H31: NO | L31: 0 | M31: 110 | O31: 0 | Q31: 90 | R31: Tirands 10MM
B32: ROPE CONNECTOR 10MM | C32: SERRE CABLE DIAM 10 * | E32: Pc | F32: 1 | G32: 0.2 | H32: NO | L32: 0 | M32: 0 | O32: 0 | Q32: 8 | R32: SERRE CABLE DIAM 10 *
B33: ROPE CONNECTOR 6MM | C33: SERRE CABLE DIAM 6 * | E33: Pc | F33: 1 | G33: 0.1 | H33: NO | L33: 0 | M33: 0 | O33: 0 | Q33: 5 | R33: SERRE CABLE DIAM 6 *
A34: OTHERS | B34: WEIGHT 96CM /50 KG PLASTIC | C34: CONTERWEIGHT BLOCK 96 CM (50 KG) | E34: Pc | F34: 1 | G34: 6 | H34: NO | L34: 340 | M34: 0 | O34: 0 | Q34: 30 | R34: CONTERWEIGHT BLOCK 96 CM (50 KG)
B35: OIL COLLECTION SET | C35: Collecteur D'huile | E35: Pc | F35: 1 | G35: 0.25 | H35: NO | L35: 0 | M35: 0 | O35: 0 | Q35: 0 | R35: Collecteur D'huile
B36: LUBRICATOR BOX | C36: BOITE DE LUBRIFICATION | E36: Pc | F36: 1 | G36: 1 | H36: NO | L36: 0 | M36: 0 | O36: 0 | Q36: 180 | R36: BOITE DE LUBRIFICATION
B37: GUIDE SHOE | C37: coulisseaux CABIN | E37: Pc | F37: 1 | G37: 0 | H37: NO | L37: 0 | M37: 0 | O37: 0 | Q37: 230 | R37: coulisseaux CABIN
B38: GUIDE SHOE PLASTIC | C38: Garniture coulisseau | E38: Pc | F38: 1 | G38: 0.5 | H38: NO | L38: 0 | M38: 0 | O38: 70 | Q38: 70 | R38: Garniture coulisseau
B39: PULLEY 5*10 | C39: POULIE RENVOI 5*10 | E39: Pc | F39: 1 | G39: 60 | H39: NO | L39: 0 | M39: 1800 | O39: 1500 | Q39: 1300 | R39: POULIE RENVOI 5*10
B40: BUFFER cabin/c.p | C40: BUFFER cabin/c.p / Les boudins - ressort dyal l7ofra | E40: SET | F40: 1 | G40: 33 | H40: NO | L40: 255 | M40: 0 | O40: 0 | Q40: 0 | R40: BUFFER cabin/c.p / Les boudins - ressort dyal l7ofra
...

Sheet Bolt Sara Adana
B6: Cost/Ton : | D6: Electrozinc plate
D7: Flat bolt
D8: 1400 Euros/ton | E8: Casa
D9: 1380 Euros/ton | E9: Adana | F9: Hex nuts only | H9: $ to Euros
B10: M8*30 BOLT | D10: BOULON 8/30 | E10: 0.07 | F10: 0.02 | G10: =+E10/F10*1000 -> 3500 | H10: =+G10*0.85 -> 2975
B11: M12*40 BOLT | D11: BOULON 12/30 COMPLET | E11: 0.2 | F11: 0.05 | G11: =+E11/F11*1000 -> 4000 | H11: =+G11*0.85 -> 3400
B12: M14*70 BOLT | D12: BOULON 14/70 | E12: 0.3 | F12: 0.09 | G12: =+E12/F12*1000 -> 3333.3333 | H12: =+G12*0.85 -> 2833.3333

Sheet Pricing Turkey
A2: Réf. | B2: FRANÇAIS | C2: Composante | D2: UNIT | E2: Poids | F2: Acier (O/N) | G2: PRICE IN TURKEY (without kdv) + LOCAL TRANSP 'USD' | H2: KDV POSSIBILITY | J2: USD / MAD | K2: 9.8 | L2: Comment
A3: IT.1 | B3: SET CABINE STANDARD INOX 1200/1100 + ARCADES & ACCESSOIRES GEARBOX | C3: CABINE & ARCADE | D3: SET | E3: 650 | F3: INOX | G3: 1500 | H3: NO
A4: IT.1-1 | B4: CABINE INOX 1000/900 STANDARD | C4: CABINE & ARCADE | D4: Pc | E4: 350 | F4: INOX | G4: 950 | L4: Without GRANITE
A5: IT.1-2 | B5: CABINE INOX 1000/900 PERSONALISÉE | C5: CABINE & ARCADE | D5: Pc | E5: 350 | F5: INOX | G5: 1200 | L5: Without GRANITE | Q5: ORD1 | R5: ORD2 | S5: ORD3 | T5: ORD4 | U5: ORD5 | V5: ORD6 | W5: ORD7 | X5: ORD8 | Y5: ORD9 | Z5: ORD10 | AA5: ORD11 | AB5: ORD12 | AC5: ORD13 | AD5: ORD14 | AE5: ORD15 | AF5: ORD16 | AG5: ORD17 | AH5: ORD18 | AI5: ORD19 | AJ5: ORD20 | AK5: ORD21 | AL5: ORD22 | AM5: ORD23 | AN5: ORD24 | AO5: ORD25 | AP5: ORD26 | AQ5: ORD27 | AR5: ORD28 | AS5: ORD29 | AT5: ORD30
A6: IT.1-3 | B6: CABINE INOX 1100/1000 STANDARD | C6: CABINE & ARCADE | D6: Pc | E6: 350 | F6: INOX | G6: 1020 | L6: Without GRANITE | Q6: 150 | R6: 150 | S6: 150 | T6: 150 | U6: 150 | V6: 150 | W6: 150 | X6: 150
A7: IT.1-4 | B7: CABINE INOX 1100/1000 PERSONALISÉE | C7: CABINE & ARCADE | D7: Pc | E7: 350 | F7: INOX | G7: 1320 | L7: Without GRANITE | Q7: 46038
A8: IT.1-5 | B8: CABINE INOX 1200/1100 STANDARD | C8: CABINE & ARCADE | D8: Pc | E8: 350 | F8: INOX | G8: 1090 | L8: Without GRANITE | Q8: 1400$ | S8: FROM 900 TO 1200 CABIN + ARCADES
A9: IT.1-6 | B9: CABINE INOX 1200/1100 PERSONALISÉE | C9: CABINE & ARCADE | D9: Pc | E9: 350 | F9: INOX | G9: 1390 | L9: Without GRANITE | Q9: 150$ | S9: PERSONALISATION
A10: IT.1-13 | B10: CABINE INOX 1400/1300 STANDARD | C10: CABINE & ARCADE | D10: SET | E10: 350 | F10: STEEL | G10: 1340 | L10: Without GRANITE
A11: IT.1-14 | B11: CABINE INOX 1400/1300 PERSONALISÉE | C11: CABINE & ARCADE | D11: SET | E11: 350 | F11: STEEL | G11: 1740 | L11: Without GRANITE
A12: IT.1-17 | B12: CABINE 1000/900 PANORAMIQUE | C12: CABINE & ARCADE | D12: Pc | E12: 350 | F12: INOX | G12: 1600
A13: IT.1-18 | B13: CABINE 1100/1000 PANORAMIQUE | C13: CABINE & ARCADE | D13: Pc | E13: 350 | F13: INOX | G13: 1700
A14: IT.1-19 | B14: CABINE 1200/1100 PANORAMIQUE | C14: CABINE & ARCADE | D14: Pc | E14: 350 | F14: INOX | G14: 1850
A15: IT.1-20 | B15: CABINE INOX 1300/1200 STANDARD | C15: CABINE & ARCADE | D15: Pc | E15: 350 | F15: INOX | G15: 1160
A16: IT.1-21 | B16: CABINE INOX 1300/1200 PERSONALISÉE | C16: CABINE & ARCADE | D16: Pc | E16: 350 | F16: INOX | G16: 1460
A17: IT.1-22 | B17: CABINE 1300/1200 PANORAMIQUE | C17: CABINE & ARCADE | D17: Pc | E17: 350 | F17: INOX | G17: 2050
A18: IT.1-23 | B18: CABINE 1400/1300 PANORAMIQUE | C18: CABINE & ARCADE | D18: Pc | E18: 350 | F18: INOX | G18: 2300
A19: IT.1-7 | B19: ARCADE CABINE 1000/900 + ARCADE CONTRE-POIDS + TIRANDS + COULISSEAUX GEARBOX | C19: CABINE & ARCADE | D19: SET | E19: 200 | F19: STEEL | G19: 450
A20: IT.1-8 | B20: ARCADE CABINE 1000/900 + ARCADE CONTRE-POIDS + TIRANDS + COULISSEAUX GEARLESS | C20: CABINE & ARCADE | D20: SET | E20: 200 | F20: STEEL | G20: 700
A21: IT.1-9 | B21: ARCADE CABINE 1100/1000 + ARCADE CONTRE-POIDS + TIRANDS + COULISSEAUX GEARBOX | C21: CABINE & ARCADE | D21: SET | E21: 200 | F21: STEEL | G21: 470
A22: IT.1-10 | B22: ARCADE CABINE 1100/1000 + ARCADE CONTRE-POIDS + TIRANDS + COULISSEAUX GEARLESS | C22: CABINE & ARCADE | D22: SET | E22: 200 | F22: STEEL | G22: 720
A23: IT.1-11 | B23: ARCADE CABINE 1200/1100 + ARCADE CONTRE-POIDS + TIRANDS + COULISSEAUX GEARBOX | C23: CABINE & ARCADE | D23: SET | E23: 200 | F23: STEEL | G23: 490 | H23: NO
A24: IT.1-12 | B24: ARCADE CABINE 1200/1100 + ARCADE CONTRE-POIDS + TIRANDS + COULISSEAUX GEARLESS | C24: CABINE & ARCADE | D24: SET | E24: 200 | F24: STEEL | G24: 740
A25: IT.1-15 | B25: ARCADE CABINE 1400/1300 + ARCADE CONTRE-POIDS + TIRANDS + COULISSEAUX GEARBOX | C25: CABINE & ARCADE | D25: SET | E25: 201 | F25: STEEL | G25: 590
A26: IT.1-16 | B26: ARCADE CABINE 1400/1300 + ARCADE CONTRE-POIDS + TIRANDS + COULISSEAUX GEARLESS | C26: CABINE & ARCADE | D26: SET | E26: 202 | F26: STEEL | G26: 940 | H26: NO
A27: IT.1-17 | B27: SET ARCADE TYPE L VVVF 2V | C27: CABINE & ARCADE | D27: SET | E27: 203 | F27: STEEL | G27: 1000
A28: IT.1-18 | B28: SET ARCADE TYPE L GEARLESS | C28: CABINE & ARCADE | D28: SET | E28: 204 | F28: STEEL | G28: 1200
A29: HYD1-1 | B29: SET SYSTÈME HYDRAULIQUE MAX4 STANDARD 0,15M/S 10M COURSE (4 NIVEAUX) | C29: HYDRAULIQUE | D29: SET | E29: 200 | F29: STEEL | G29: 1500
A30: HYD1-2 | B30: SET SYSTÈME HYDRAULIQUE MAX4 STANDARD 0,15M/S 7M COURSE (3 NIVEAUX) | C30: HYDRAULIQUE | D30: SET | E30: 198 | F30: STEEL
A31: HYD1-3 | B31: SET SYSTÈME HYDRAULIQUE MAX4 STANDARD 0,15M/S 4M COURSE (2 NIVEAUX) | C31: HYDRAULIQUE | D31: SET | E31: 199 | F31: STEEL
A32: HYD2-1 | B32: SET SYSTÈME HYDRAULIQUE MAX4 GMV 0,62M/S 10M COURSE (4 NIVEAUX) | C32: HYDRAULIQUE | D32: SET | E32: 200 | F32: STEEL | G32: =3000*1.1 -> 3300
A33: HYD2-2 | B33: SET SYSTÈME HYDRAULIQUE MAX4 GMV 0,62M/S 7M COURSE (3 NIVEAUX) | C33: HYDRAULIQUE | D33: SET | E33: 200 | F33: STEEL | G33: 3000
A34: HYD2-3 | B34: SET SYSTÈME HYDRAULIQUE MAX4 GMV 0,62M/S 4M COURSE (2 NIVEAUX) | C34: HYDRAULIQUE | D34: SET | E34: 200 | F34: STEEL | G34: 2700
A35: HYD3 | B35: SET COMPOSANTES ELECTRIQUES POUR SYSTEME HYDRAULIQUE | C35: HYDRAULIQUE | D35: SET | E35: 200 | F35: STEEL | G35: 800
A36: HYD4 | B36: HUILE HYDRAULIQUE | C36: HYDRAULIQUE | D36: L | E36: 1 | F36: OIL | G36: 4
A37: IT.2 | B37: PORTE PALIERE AUTOMATIQUE INOX ATERYA 70/80 | C37: PORTE | D37: Pc | E37: 145 | F37: INOX | G37: 252.7436 | H37: NO | K37: Fournisseur au Maroc
A38: IT.3 | B38: PORTE PALIERE AUTOMATIQUE EPOXY ATERYA 70/80 | C38: PORTE | D38: Pc | E38: 140 | F38: STEEL | G38: 186.23213 | H38: NO | K38: Fournisseur au Maroc
A39: IT.4 | B39: OPERATEUR INOX ATERYA 70/80 | C39: OPÉRATEUR | D39: Pc | E39: 38 | F39: INOX | G39: 419.02228 | H39: NO | K39: Fournisseur au Maroc
A40: IT.5 | B40: SEMI AUTOMATIC PORTE EPOXY 70/80 | C40: PORTE | D40: Pc | E40: 90 | F40: STEEL | G40: 110 | H40: NO
A41: IT.6 | B41: SEMI AUTOMATIC PORTE INOX 70/80 | C41: PORTE | D41: Pc | E41: 90 | F41: INOX | G41: 110 | H41: yes
...

Sheet Pricing sheet
B2: Items Pricing Order Lift Morocco | I2: 2835
H3: =20%*9310 -> 1862 | I3: =+G34*20.25% -> 2897.37
E4: Hypothèse : conteneur par mois de vente d'une valeur de 250000 MAD, 2 recrues full time
E5: Nombre de conteneur par mois | F5: Valeur de conteneur | G5: 1 | H5: 300000
G6: USD to MAD | I6: Aléas transport | J6: Comission vente (sur prix initial)
G7: =+'Pricing Turkey'!K2 -> 9.8 | I7: 0.15 | J7: 0.03 | K7: 0.07 | L7: 0.25
I8: Prix conteneur en USD | J8: Charges par mois
I9: 1500 | J9: =SUM(J11:J17) -> 54700
I10: Prix camion TTC | J10: Voitures amortissement
I11: 3700 | J11: 8000
I12: Déchargement | J12: RH
I13: 1000 | J13: 35000
I14: Chargement | J14: Location (bureau + stock)
I15: 1000 | J15: =4700+3500 -> 8200
I16: Frais de Port et agent maritime | J16: Comptable et autre
I17: 5000 | J17: 3500
A20: Ref | B20: Description | C20: Composante | D20: Unité | E20: Poids | F20: Acier (O/N) | G20: Prix Turquie | H20: Douane | I20: Transport & Transitaire | J20: Charge équipe/bureau | K20: Impots | L20: Marge | M20: Prix final sans stock (min) | N20: Prix final sans stock (max) | O20: Prix final stock
A21: =+'Pricing Turkey'!A3 -> IT.1 | B21: =+'Pricing Turkey'!B3 -> SET CABINE STANDARD INOX 1200/1100 + ARCADES & ACCESSOIRES GEARBOX | C21: =+'Pricing Turkey'!C3 -> CABINE & ARCADE | D21: =+'Pricing Turkey'!D3 -> SET | E21: =+'Pricing Turkey'!E3 -> 650 | F21: =+'Pricing Turkey'!F3 -> INOX | G21: ='Pricing Turkey'!G3*G$7 -> 14700 | H21: =IF(F21="STEEL",MAX(G21,E21*13)*20.25%,IF(F21="GALVA",MAX(G21,E21*24)*20.25%,IF(F21="INOX",MAX(G21,E21*40)*20.25%,IF(F21="COPPER",MAX(G21,E21*60)*20.25%,G21*20.25%)))) -> 5265 | I21: =+((I$9*G$7+I$11+I$13+I$15+I$17)*(1+I$7)+2500)/($G$5*$H$5)*G21 -> 1553.79 | J21: =(J$9+J$7*G21)/($G$5*$H$5)*G21 -> 2701.909 | K21: =K$7*G21 -> 1029 | L21: =+G21*L$7 -> 3675 | M21: =+G21+H21+I21+J21*50%+K21+L21*30% -> 25001.245 | N21: =+G21+H21+I21+J21*50%+K21+L21*50% -> 25736.245 | O21: =+SUM(H21:L21)+G21 -> 28924.699
A22: =+'Pricing Turkey'!A4 -> IT.1-1 | B22: =+'Pricing Turkey'!B4 -> CABINE INOX 1000/900 STANDARD | C22: =+'Pricing Turkey'!C4 -> CABINE & ARCADE | D22: =+'Pricing Turkey'!D4 -> Pc | E22: =+'Pricing Turkey'!E4 -> 350 | F22: =+'Pricing Turkey'!F4 -> INOX | G22: ='Pricing Turkey'!G4*G$7 -> 9310 | H22: =IF(F22="STEEL",MAX(G22,E22*13)*20.25%,IF(F22="GALVA",MAX(G22,E22*24)*20.25%,IF(F22="INOX",MAX(G22,E22*40)*20.25%,IF(F22="COPPER",MAX(G22,E22*60)*20.25%,G22*20.25%)))) -> 2835 | I22: =+((I$9*G$7+I$11+I$13+I$15+I$17)*(1+I$7)+2500)/($G$5*$H$5)*G22 -> 984.067 | J22: =(J$9+J$7*G22)/($G$5*$H$5)*G22 -> 1706.1909 | K22: =K$7*G22 -> 651.7 | L22: =+G22*L$7 -> 2327.5 | M22: =+G22+H22+I22+J22*50%+K22+L22*30% -> 15332.112 | N22: =+G22+H22+I22+J22*50%+K22+L22*50% -> 15797.612 | O22: =+SUM(H22:L22)+G22 -> 17814.458
A23: =+'Pricing Turkey'!A5 -> IT.1-2 | B23: =+'Pricing Turkey'!B5 -> CABINE INOX 1000/900 PERSONALISÉE | C23: =+'Pricing Turkey'!C5 -> CABINE & ARCADE | D23: =+'Pricing Turkey'!D5 -> Pc | E23: =+'Pricing Turkey'!E5 -> 350 | F23: =+'Pricing Turkey'!F5 -> INOX | G23: ='Pricing Turkey'!G5*G$7 -> 11760 | H23: =IF(F23="STEEL",MAX(G23,E23*13)*20.25%,IF(F23="GALVA",MAX(G23,E23*24)*20.25%,IF(F23="INOX",MAX(G23,E23*40)*20.25%,IF(F23="COPPER",MAX(G23,E23*60)*20.25%,G23*20.25%)))) -> 2835 | I23: =+((I$9*G$7+I$11+I$13+I$15+I$17)*(1+I$7)+2500)/($G$5*$H$5)*G23 -> 1243.032 | J23: =(J$9+J$7*G23)/($G$5*$H$5)*G23 -> 2158.0698 | K23: =K$7*G23 -> 823.2 | L23: =+G23*L$7 -> 2940 | M23: =+G23+H23+I23+J23*50%+K23+L23*30% -> 18622.267 | N23: =+G23+H23+I23+J23*50%+K23+L23*50% -> 19210.267 | O23: =+SUM(H23:L23)+G23 -> 21759.302
A24: =+'Pricing Turkey'!A6 -> IT.1-3 | B24: =+'Pricing Turkey'!B6 -> CABINE INOX 1100/1000 STANDARD | C24: =+'Pricing Turkey'!C6 -> CABINE & ARCADE | D24: =+'Pricing Turkey'!D6 -> Pc | E24: =+'Pricing Turkey'!E6 -> 350 | F24: =+'Pricing Turkey'!F6 -> INOX | G24: ='Pricing Turkey'!G6*G$7 -> 9996 | H24: =IF(F24="STEEL",MAX(G24,E24*13)*20.25%,IF(F24="GALVA",MAX(G24,E24*24)*20.25%,IF(F24="INOX",MAX(G24,E24*40)*20.25%,IF(F24="COPPER",MAX(G24,E24*60)*20.25%,G24*20.25%)))) -> 2835 | I24: =+((I$9*G$7+I$11+I$13+I$15+I$17)*(1+I$7)+2500)/($G$5*$H$5)*G24 -> 1056.5772 | J24: =(J$9+J$7*G24)/($G$5*$H$5)*G24 -> 1832.596 | K24: =K$7*G24 -> 699.72 | L24: =+G24*L$7 -> 2499 | M24: =+G24+H24+I24+J24*50%+K24+L24*30% -> 16253.295 | N24: =+G24+H24+I24+J24*50%+K24+L24*50% -> 16753.095 | O24: =+SUM(H24:L24)+G24 -> 18918.893
A25: =+'Pricing Turkey'!A7 -> IT.1-4 | B25: =+'Pricing Turkey'!B7 -> CABINE INOX 1100/1000 PERSONALISÉE | C25: =+'Pricing Turkey'!C7 -> CABINE & ARCADE | D25: =+'Pricing Turkey'!D7 -> Pc | E25: =+'Pricing Turkey'!E7 -> 350 | F25: =+'Pricing Turkey'!F7 -> INOX | G25: ='Pricing Turkey'!G7*G$7 -> 12936 | H25: =IF(F25="STEEL",MAX(G25,E25*13)*20.25%,IF(F25="GALVA",MAX(G25,E25*24)*20.25%,IF(F25="INOX",MAX(G25,E25*40)*20.25%,IF(F25="COPPER",MAX(G25,E25*60)*20.25%,G25*20.25%)))) -> 2835 | I25: =+((I$9*G$7+I$11+I$13+I$15+I$17)*(1+I$7)+2500)/($G$5*$H$5)*G25 -> 1367.3352 | J25: =(J$9+J$7*G25)/($G$5*$H$5)*G25 -> 2375.398 | K25: =K$7*G25 -> 905.52 | L25: =+G25*L$7 -> 3234 | M25: =+G25+H25+I25+J25*50%+K25+L25*30% -> 20201.754 | N25: =+G25+H25+I25+J25*50%+K25+L25*50% -> 20848.554 | O25: =+SUM(H25:L25)+G25 -> 23653.253
A26: =+'Pricing Turkey'!A8 -> IT.1-5 | B26: =+'Pricing Turkey'!B8 -> CABINE INOX 1200/1100 STANDARD | C26: =+'Pricing Turkey'!C8 -> CABINE & ARCADE | D26: =+'Pricing Turkey'!D8 -> Pc | E26: =+'Pricing Turkey'!E8 -> 350 | F26: =+'Pricing Turkey'!F8 -> INOX | G26: ='Pricing Turkey'!G8*G$7 -> 10682 | H26: =IF(F26="STEEL",MAX(G26,E26*13)*20.25%,IF(F26="GALVA",MAX(G26,E26*24)*20.25%,IF(F26="INOX",MAX(G26,E26*40)*20.25%,IF(F26="COPPER",MAX(G26,E26*60)*20.25%,G26*20.25%)))) -> 2835 | I26: =+((I$9*G$7+I$11+I$13+I$15+I$17)*(1+I$7)+2500)/($G$5*$H$5)*G26 -> 1129.0874 | J26: =(J$9+J$7*G26)/($G$5*$H$5)*G26 -> 1959.0952 | K26: =K$7*G26 -> 747.74 | L26: =+G26*L$7 -> 2670.5 | M26: =+G26+H26+I26+J26*50%+K26+L26*30% -> 17174.525 | N26: =+G26+H26+I26+J26*50%+K26+L26*50% -> 17708.625 | O26: =+SUM(H26:L26)+G26 -> 20023.423
A27: =+'Pricing Turkey'!A9 -> IT.1-6 | B27: =+'Pricing Turkey'!B9 -> CABINE INOX 1200/1100 PERSONALISÉE | C27: =+'Pricing Turkey'!C9 -> CABINE & ARCADE | D27: =+'Pricing Turkey'!D9 -> Pc | E27: =+'Pricing Turkey'!E9 -> 350 | F27: =+'Pricing Turkey'!F9 -> INOX | G27: ='Pricing Turkey'!G9*G$7 -> 13622 | H27: =IF(F27="STEEL",MAX(G27,E27*13)*20.25%,IF(F27="GALVA",MAX(G27,E27*24)*20.25%,IF(F27="INOX",MAX(G27,E27*40)*20.25%,IF(F27="COPPER",MAX(G27,E27*60)*20.25%,G27*20.25%)))) -> 2835 | I27: =+((I$9*G$7+I$11+I$13+I$15+I$17)*(1+I$7)+2500)/($G$5*$H$5)*G27 -> 1439.8454 | J27: =(J$9+J$7*G27)/($G$5*$H$5)*G27 -> 2502.3006 | K27: =K$7*G27 -> 953.54 | L27: =+G27*L$7 -> 3405.5 | M27: =+G27+H27+I27+J27*50%+K27+L27*30% -> 21123.186 | N27: =+G27+H27+I27+J27*50%+K27+L27*50% -> 21804.286 | O27: =+SUM(H27:L27)+G27 -> 24758.186
A28: =+'Pricing Turkey'!A10 -> IT.1-13 | B28: =+'Pricing Turkey'!B10 -> CABINE INOX 1400/1300 STANDARD | C28: =+'Pricing Turkey'!C10 -> CABINE & ARCADE | D28: =+'Pricing Turkey'!D10 -> SET | E28: =+'Pricing Turkey'!E10 -> 350 | F28: =+'Pricing Turkey'!F10 -> STEEL | G28: ='Pricing Turkey'!G10*G$7 -> 13132 | H28: =IF(F28="STEEL",MAX(G28,E28*13)*20.25%,IF(F28="GALVA",MAX(G28,E28*24)*20.25%,IF(F28="INOX",MAX(G28,E28*40)*20.25%,IF(F28="COPPER",MAX(G28,E28*60)*20.25%,G28*20.25%)))) -> 2659.23 | I28: =+((I$9*G$7+I$11+I$13+I$15+I$17)*(1+I$7)+2500)/($G$5*$H$5)*G28 -> 1388.0524 | J28: =(J$9+J$7*G28)/($G$5*$H$5)*G28 -> 2411.6463 | K28: =K$7*G28 -> 919.24 | L28: =+G28*L$7 -> 3283 | M28: =+G28+H28+I28+J28*50%+K28+L28*30% -> 20289.246 | N28: =+G28+H28+I28+J28*50%+K28+L28*50% -> 20945.846 | O28: =+SUM(H28:L28)+G28 -> 23793.169
A29: =+'Pricing Turkey'!A11 -> IT.1-14 | B29: =+'Pricing Turkey'!B11 -> CABINE INOX 1400/1300 PERSONALISÉE | C29: =+'Pricing Turkey'!C11 -> CABINE & ARCADE | D29: =+'Pricing Turkey'!D11 -> SET | E29: =+'Pricing Turkey'!E11 -> 350 | F29: =+'Pricing Turkey'!F11 -> STEEL | G29: ='Pricing Turkey'!G11*G$7 -> 17052 | H29: =IF(F29="STEEL",MAX(G29,E29*13)*20.25%,IF(F29="GALVA",MAX(G29,E29*24)*20.25%,IF(F29="INOX",MAX(G29,E29*40)*20.25%,IF(F29="COPPER",MAX(G29,E29*60)*20.25%,G29*20.25%)))) -> 3453.03 | I29: =+((I$9*G$7+I$11+I$13+I$15+I$17)*(1+I$7)+2500)/($G$5*$H$5)*G29 -> 1802.3964 | J29: =(J$9+J$7*G29)/($G$5*$H$5)*G29 -> 3138.2251 | K29: =K$7*G29 -> 1193.64 | L29: =+G29*L$7 -> 4263 | M29: =+G29+H29+I29+J29*50%+K29+L29*30% -> 26349.079 | N29: =+G29+H29+I29+J29*50%+K29+L29*50% -> 27201.679 | O29: =+SUM(H29:L29)+G29 -> 30902.291
A30: =+'Pricing Turkey'!A12 -> IT.1-17 | B30: =+'Pricing Turkey'!B12 -> CABINE 1000/900 PANORAMIQUE | C30: =+'Pricing Turkey'!C12 -> CABINE & ARCADE | D30: =+'Pricing Turkey'!D12 -> Pc | E30: =+'Pricing Turkey'!E12 -> 350 | F30: =+'Pricing Turkey'!F12 -> INOX | G30: ='Pricing Turkey'!G12*G$7 -> 15680 | H30: =IF(F30="STEEL",MAX(G30,E30*13)*20.25%,IF(F30="GALVA",MAX(G30,E30*24)*20.25%,IF(F30="INOX",MAX(G30,E30*40)*20.25%,IF(F30="COPPER",MAX(G30,E30*60)*20.25%,G30*20.25%)))) -> 3175.2 | I30: =+((I$9*G$7+I$11+I$13+I$15+I$17)*(1+I$7)+2500)/($G$5*$H$5)*G30 -> 1657.376 | J30: =(J$9+J$7*G30)/($G$5*$H$5)*G30 -> 2883.5729 | K30: =K$7*G30 -> 1097.6 | L30: =+G30*L$7 -> 3920 | M30: =+G30+H30+I30+J30*50%+K30+L30*30% -> 24227.962 | N30: =+G30+H30+I30+J30*50%+K30+L30*50% -> 25011.962 | O30: =+SUM(H30:L30)+G30 -> 28413.749
A31: =+'Pricing Turkey'!A13 -> IT.1-18 | B31: =+'Pricing Turkey'!B13 -> CABINE 1100/1000 PANORAMIQUE | C31: =+'Pricing Turkey'!C13 -> CABINE & ARCADE | D31: =+'Pricing Turkey'!D13 -> Pc | E31: =+'Pricing Turkey'!E13 -> 350 | F31: =+'Pricing Turkey'!F13 -> INOX | G31: ='Pricing Turkey'!G13*G$7 -> 16660 | H31: =IF(F31="STEEL",MAX(G31,E31*13)*20.25%,IF(F31="GALVA",MAX(G31,E31*24)*20.25%,IF(F31="INOX",MAX(G31,E31*40)*20.25%,IF(F31="COPPER",MAX(G31,E31*60)*20.25%,G31*20.25%)))) -> 3373.65 | I31: =+((I$9*G$7+I$11+I$13+I$15+I$17)*(1+I$7)+2500)/($G$5*$H$5)*G31 -> 1760.962 | J31: =(J$9+J$7*G31)/($G$5*$H$5)*G31 -> 3065.4289 | K31: =K$7*G31 -> 1166.2 | L31: =+G31*L$7 -> 4165 | M31: =+G31+H31+I31+J31*50%+K31+L31*30% -> 25743.026 | N31: =+G31+H31+I31+J31*50%+K31+L31*50% -> 26576.026 | O31: =+SUM(H31:L31)+G31 -> 30191.241
A32: =+'Pricing Turkey'!A14 -> IT.1-19 | B32: =+'Pricing Turkey'!B14 -> CABINE 1200/1100 PANORAMIQUE | C32: =+'Pricing Turkey'!C14 -> CABINE & ARCADE | D32: =+'Pricing Turkey'!D14 -> Pc | E32: =+'Pricing Turkey'!E14 -> 350 | F32: =+'Pricing Turkey'!F14 -> INOX | G32: ='Pricing Turkey'!G14*G$7 -> 18130 | H32: =IF(F32="STEEL",MAX(G32,E32*13)*20.25%,IF(F32="GALVA",MAX(G32,E32*24)*20.25%,IF(F32="INOX",MAX(G32,E32*40)*20.25%,IF(F32="COPPER",MAX(G32,E32*60)*20.25%,G32*20.25%)))) -> 3671.325 | I32: =+((I$9*G$7+I$11+I$13+I$15+I$17)*(1+I$7)+2500)/($G$5*$H$5)*G32 -> 1916.341 | J32: =(J$9+J$7*G32)/($G$5*$H$5)*G32 -> 3338.573 | K32: =K$7*G32 -> 1269.1 | L32: =+G32*L$7 -> 4532.5 | M32: =+G32+H32+I32+J32*50%+K32+L32*30% -> 28015.803 | N32: =+G32+H32+I32+J32*50%+K32+L32*50% -> 28922.303 | O32: =+SUM(H32:L32)+G32 -> 32857.839
... A36: =+'Pricing Turkey'!A18 -> IT.1-23 | B36: =+'Pricing Turkey'!B18 -> CABINE 1400/1300 PANORAMIQUE | C36: =+'Pricing Turkey'!C18 -> CABINE & ARCADE | D36: =+'Pricing Turkey'!D18 -> Pc | E36: =+'Pricing Turkey'!E18 -> 350 | F36: =+'Pricing Turkey'!F18 -> INOX | G36: ='Pricing Turkey'!G18*G$7 -> 22540 | H36: =IF(F36="STEEL",MAX(G36,E36*13)*20.25%,IF(F36="GALVA",MAX(G36,E36*24)*20.25%,IF(F36="INOX",MAX(G36,E36*40)*20.25%,IF(F36="COPPER",MAX(G36,E36*60)*20.25%,G36*20.25%)))) -> 4564.35 | I36: =+((I$9*G$7+I$11+I$13+I$15+I$17)*(1+I$7)+2500)/($G$5*$H$5)*G36 -> 2382.478 | J36: =(J$9+J$7*G36)/($G$5*$H$5)*G36 -> 4160.5985 | K36: =K$7*G36 -> 1577.8 | L36: =+G36*L$7 -> 5635 | M36: =+G36+H36+I36+J36*50%+K36+L36*30% -> 34835.427 | N36: =+G36+H36+I36+J36*50%+K36+L36*50% -> 35962.427 | O36: =+SUM(H36:L36)+G36 -> 40860.226
A37: =+'Pricing Turkey'!A19 -> IT.1-7 | B37: =+'Pricing Turkey'!B19 -> ARCADE CABINE 1000/900 + ARCADE CONTRE-POIDS + TIRANDS + COULISSEAUX GEARBOX | C37: =+'Pricing Turkey'!C19 -> CABINE & ARCADE | D37: =+'Pricing Turkey'!D19 -> SET | E37: =+'Pricing Turkey'!E19 -> 200 | F37: =+'Pricing Turkey'!F19 -> STEEL | G37: ='Pricing Turkey'!G19*G$7 -> 4410 | H37: =IF(F37="STEEL",MAX(G37,E37*13)*20.25%,IF(F37="GALVA",MAX(G37,E37*24)*20.25%,IF(F37="INOX",MAX(G37,E37*40)*20.25%,IF(F37="COPPER",MAX(G37,E37*60)*20.25%,G37*20.25%)))) -> 893.025 | I37: =+((I$9*G$7+I$11+I$13+I$15+I$17)*(1+I$7)+2500)/($G$5*$H$5)*G37 -> 466.137 | J37: =(J$9+J$7*G37)/($G$5*$H$5)*G37 -> 806.03481 | K37: =K$7*G37 -> 308.7 | L37: =+G37*L$7 -> 1102.5 | M37: =+G37+H37+I37+J37*50%+K37+L37*30% -> 6811.6294 | N37: =+G37+H37+I37+J37*50%+K37+L37*70% -> 7252.6294 | O37: =+SUM(H37:L37)+G37 -> 7986.3968
A38: =+'Pricing Turkey'!A20 -> IT.1-8 | B38: =+'Pricing Turkey'!B20 -> ARCADE CABINE 1000/900 + ARCADE CONTRE-POIDS + TIRANDS + COULISSEAUX GEARLESS | C38: =+'Pricing Turkey'!C20 -> CABINE & ARCADE | D38: =+'Pricing Turkey'!D20 -> SET | E38: =+'Pricing Turkey'!E20 -> 200 | F38: =+'Pricing Turkey'!F20 -> STEEL | G38: ='Pricing Turkey'!G20*G$7 -> 6860 | H38: =IF(F38="STEEL",MAX(G38,E38*13)*20.25%,IF(F38="GALVA",MAX(G38,E38*24)*20.25%,IF(F38="INOX",MAX(G38,E38*40)*20.25%,IF(F38="COPPER",MAX(G38,E38*60)*20.25%,G38*20.25%)))) -> 1389.15 | I38: =+((I$9*G$7+I$11+I$13+I$15+I$17)*(1+I$7)+2500)/($G$5*$H$5)*G38 -> 725.102 | J38: =(J$9+J$7*G38)/($G$5*$H$5)*G38 -> 1255.5126 | K38: =K$7*G38 -> 480.2 | L38: =+G38*L$7 -> 1715 | M38: =+G38+H38+I38+J38*50%+K38+L38*30% -> 10596.708 | N38: =+G38+H38+I38+J38*50%+K38+L38*70% -> 11282.708 | O38: =+SUM(H38:L38)+G38 -> 12424.965
A39: =+'Pricing Turkey'!A21 -> IT.1-9 | B39: =+'Pricing Turkey'!B21 -> ARCADE CABINE 1100/1000 + ARCADE CONTRE-POIDS + TIRANDS + COULISSEAUX GEARBOX | C39: =+'Pricing Turkey'!C21 -> CABINE & ARCADE | D39: =+'Pricing Turkey'!D21 -> SET | E39: =+'Pricing Turkey'!E21 -> 200 | F39: =+'Pricing Turkey'!F21 -> STEEL | G39: ='Pricing Turkey'!G21*G$7 -> 4606 | H39: =IF(F39="STEEL",MAX(G39,E39*13)*20.25%,IF(F39="GALVA",MAX(G39,E39*24)*20.25%,IF(F39="INOX",MAX(G39,E39*40)*20.25%,IF(F39="COPPER",MAX(G39,E39*60)*20.25%,G39*20.25%)))) -> 932.715 | I39: =+((I$9*G$7+I$11+I$13+I$15+I$17)*(1+I$7)+2500)/($G$5*$H$5)*G39 -> 486.8542 | J39: =(J$9+J$7*G39)/($G$5*$H$5)*G39 -> 841.94886 | K39: =K$7*G39 -> 322.42 | L39: =+G39*L$7 -> 1151.5 | M39: =+G39+H39+I39+J39*50%+K39+L39*30% -> 7114.4136 | N39: =+G39+H39+I39+J39*50%+K39+L39*70% -> 7575.0136 | O39: =+SUM(H39:L39)+G39 -> 8341.4381
A40: =+'Pricing Turkey'!A22 -> IT.1-10 | B40: =+'Pricing Turkey'!B22 -> ARCADE CABINE 1100/1000 + ARCADE CONTRE-POIDS + TIRANDS + COULISSEAUX GEARLESS | C40: =+'Pricing Turkey'!C22 -> CABINE & ARCADE | D40: =+'Pricing Turkey'!D22 -> SET | E40: =+'Pricing Turkey'!E22 -> 200 | F40: =+'Pricing Turkey'!F22 -> STEEL | G40: ='Pricing Turkey'!G22*G$7 -> 7056 | H40: =IF(F40="STEEL",MAX(G40,E40*13)*20.25%,IF(F40="GALVA",MAX(G40,E40*24)*20.25%,IF(F40="INOX",MAX(G40,E40*40)*20.25%,IF(F40="COPPER",MAX(G40,E40*60)*20.25%,G40*20.25%)))) -> 1428.84 | I40: =+((I$9*G$7+I$11+I$13+I$15+I$17)*(1+I$7)+2500)/($G$5*$H$5)*G40 -> 745.8192 | J40: =(J$9+J$7*G40)/($G$5*$H$5)*G40 -> 1291.5227 | K40: =K$7*G40 -> 493.92 | L40: =+G40*L$7 -> 1764 | M40: =+G40+H40+I40+J40*50%+K40+L40*30% -> 10899.541 | N40: =+G40+H40+I40+J40*50%+K40+L40*70% -> 11605.141 | O40: =+SUM(H40:L40)+G40 -> 12780.102
A41: =+'Pricing Turkey'!A23 -> IT.1-11 | B41: =+'Pricing Turkey'!B23 -> ARCADE CABINE 1200/1100 + ARCADE CONTRE-POIDS + TIRANDS + COULISSEAUX GEARBOX | C41: =+'Pricing Turkey'!C23 -> CABINE & ARCADE | D41: =+'Pricing Turkey'!D23 -> SET | E41: =+'Pricing Turkey'!E23 -> 200 | F41: =+'Pricing Turkey'!F23 -> STEEL | G41: ='Pricing Turkey'!G23*G$7 -> 4802 | H41: =IF(F41="STEEL",MAX(G41,E41*13)*20.25%,IF(F41="GALVA",MAX(G41,E41*24)*20.25%,IF(F41="INOX",MAX(G41,E41*40)*20.25%,IF(F41="COPPER",MAX(G41,E41*60)*20.25%,G41*20.25%)))) -> 972.405 | I41: =+((I$9*G$7+I$11+I$13+I$15+I$17)*(1+I$7)+2500)/($G$5*$H$5)*G41 -> 507.5714 | J41: =(J$9+J$7*G41)/($G$5*$H$5)*G41 -> 877.87059 | K41: =K$7*G41 -> 336.14 | L41: =+G41*L$7 -> 1200.5 | M41: =+G41+H41+I41+J41*50%+K41+L41*30% -> 7417.2017 | N41: =+G41+H41+I41+J41*50%+K41+L41*70% -> 7897.4017 | O41: =+SUM(H41:L41)+G41 -> 8696.487
A42: =+'Pricing Turkey'!A24 -> IT.1-12 | B42: =+'Pricing Turkey'!B24 -> ARCADE CABINE 1200/1100 + ARCADE CONTRE-POIDS + TIRANDS + COULISSEAUX GEARLESS | C42: =+'Pricing Turkey'!C24 -> CABINE & ARCADE | D42: =+'Pricing Turkey'!D24 -> SET | E42: =+'Pricing Turkey'!E24 -> 200 | F42: =+'Pricing Turkey'!F24 -> STEEL | G42: ='Pricing Turkey'!G24*G$7 -> 7252 | H42: =IF(F42="STEEL",MAX(G42,E42*13)*20.25%,IF(F42="GALVA",MAX(G42,E42*24)*20.25%,IF(F42="INOX",MAX(G42,E42*40)*20.25%,IF(F42="COPPER",MAX(G42,E42*60)*20.25%,G42*20.25%)))) -> 1468.53 | I42: =+((I$9*G$7+I$11+I$13+I$15+I$17)*(1+I$7)+2500)/($G$5*$H$5)*G42 -> 766.5364 | J42: =(J$9+J$7*G42)/($G$5*$H$5)*G42 -> 1327.5405 | K42: =K$7*G42 -> 507.64 | L42: =+G42*L$7 -> 1813 | M42: =+G42+H42+I42+J42*50%+K42+L42*30% -> 11202.377 | N42: =+G42+H42+I42+J42*50%+K42+L42*70% -> 11927.577 | O42: =+SUM(H42:L42)+G42 -> 13135.247
A43: =+'Pricing Turkey'!A25 -> IT.1-15 | B43: =+'Pricing Turkey'!B25 -> ARCADE CABINE 1400/1300 + ARCADE CONTRE-POIDS + TIRANDS + COULISSEAUX GEARBOX | C43: =+'Pricing Turkey'!C25 -> CABINE & ARCADE | D43: =+'Pricing Turkey'!D25 -> SET | E43: =+'Pricing Turkey'!E25 -> 201 | F43: =+'Pricing Turkey'!F25 -> STEEL | G43: ='Pricing Turkey'!G25*G$7 -> 5782 | H43: =IF(F43="STEEL",MAX(G43,E43*13)*20.25%,IF(F43="GALVA",MAX(G43,E43*24)*20.25%,IF(F43="INOX",MAX(G43,E43*40)*20.25%,IF(F43="COPPER",MAX(G43,E43*60)*20.25%,G43*20.25%)))) -> 1170.855 | I43: =+((I$9*G$7+I$11+I$13+I$15+I$17)*(1+I$7)+2500)/($G$5*$H$5)*G43 -> 611.1574 | J43: =(J$9+J$7*G43)/($G$5*$H$5)*G43 -> 1057.5945 | K43: =K$7*G43 -> 404.74 | L43: =+G43*L$7 -> 1445.5 | M43: =+G43+H43+I43+J43*50%+K43+L43*30% -> 8931.1996 | N43: =+G43+H43+I43+J43*50%+K43+L43*70% -> 9509.3996 | O43: =+SUM(H43:L43)+G43 -> 10471.847
A44: =+'Pricing Turkey'!A26 -> IT.1-16 | B44: =+'Pricing Turkey'!B26 -> ARCADE CABINE 1400/1300 + ARCADE CONTRE-POIDS + TIRANDS + COULISSEAUX GEARLESS | C44: =+'Pricing Turkey'!C26 -> CABINE & ARCADE | D44: =+'Pricing Turkey'!D26 -> SET | E44: =+'Pricing Turkey'!E26 -> 202 | F44: =+'Pricing Turkey'!F26 -> STEEL | G44: ='Pricing Turkey'!G26*G$7 -> 9212 | H44: =IF(F44="STEEL",MAX(G44,E44*13)*20.25%,IF(F44="GALVA",MAX(G44,E44*24)*20.25%,IF(F44="INOX",MAX(G44,E44*40)*20.25%,IF(F44="COPPER",MAX(G44,E44*60)*20.25%,G44*20.25%)))) -> 1865.43 | I44: =+((I$9*G$7+I$11+I$13+I$15+I$17)*(1+I$7)+2500)/($G$5*$H$5)*G44 -> 973.7084 | J44: =(J$9+J$7*G44)/($G$5*$H$5)*G44 -> 1688.1408 | K44: =K$7*G44 -> 644.84 | L44: =+G44*L$7 -> 2303 | M44: =+G44+H44+I44+J44*50%+K44+L44*30% -> 14230.949 | N44: =+G44+H44+I44+J44*50%+K44+L44*70% -> 15152.149 | O44: =+SUM(H44:L44)+G44 -> 16687.119
A45: =+'Pricing Turkey'!A27 -> IT.1-17 | B45: =+'Pricing Turkey'!B27 -> SET ARCADE TYPE L VVVF 2V | C45: =+'Pricing Turkey'!C27 -> CABINE & ARCADE | D45: =+'Pricing Turkey'!D27 -> SET | E45: =+'Pricing Turkey'!E27 -> 203 | F45: =+'Pricing Turkey'!F27 -> STEEL | G45: ='Pricing Turkey'!G27*G$7 -> 9800 | H45: =IF(F45="STEEL",MAX(G45,E45*13)*20.25%,IF(F45="GALVA",MAX(G45,E45*24)*20.25%,IF(F45="INOX",MAX(G45,E45*40)*20.25%,IF(F45="COPPER",MAX(G45,E45*60)*20.25%,G45*20.25%)))) -> 1984.5 | I45: =+((I$9*G$7+I$11+I$13+I$15+I$17)*(1+I$7)+2500)/($G$5*$H$5)*G45 -> 1035.86 | J45: =(J$9+J$7*G45)/($G$5*$H$5)*G45 -> 1796.4707 | K45: =K$7*G45 -> 686 | L45: =+G45*L$7 -> 2450 | M45: =+G45+H45+I45+J45*50%+K45+L45*30% -> 15139.595 | N45: =+G45+H45+I45+J45*50%+K45+L45*70% -> 16119.595 | O45: =+SUM(H45:L45)+G45 -> 17752.831
A46: =+'Pricing Turkey'!A28 -> IT.1-18 | B46: =+'Pricing Turkey'!B28 -> SET ARCADE TYPE L GEARLESS | C46: =+'Pricing Turkey'!C28 -> CABINE & ARCADE | D46: =+'Pricing Turkey'!D28 -> SET | E46: =+'Pricing Turkey'!E28 -> 204 | F46: =+'Pricing Turkey'!F28 -> STEEL | G46: ='Pricing Turkey'!G28*G$7 -> 11760 | H46: =IF(F46="STEEL",MAX(G46,E46*13)*20.25%,IF(F46="GALVA",MAX(G46,E46*24)*20.25%,IF(F46="INOX",MAX(G46,E46*40)*20.25%,IF(F46="COPPER",MAX(G46,E46*60)*20.25%,G46*20.25%)))) -> 2381.4 | I46: =+((I$9*G$7+I$11+I$13+I$15+I$17)*(1+I$7)+2500)/($G$5*$H$5)*G46 -> 1243.032 | J46: =(J$9+J$7*G46)/($G$5*$H$5)*G46 -> 2158.0698 | K46: =K$7*G46 -> 823.2 | L46: =+G46*L$7 -> 2940 | M46: =+G46+H46+I46+J46*50%+K46+L46*30% -> 18168.667 | N46: =+G46+H46+I46+J46*50%+K46+L46*70% -> 19344.667 | O46: =+SUM(H46:L46)+G46 -> 21305.702
...

Sheet Pricing sheet clean
E1: Pricing | F1: Type | G1: Nombre de personne | H1: Nombre de niveau | I1: Moteur marque | J1: Porte marque | K1: Porte matériau | L1: Porte type | M1: Porte dimension | N1: Moteur capacité
B2: Items Pricing Order Lift Morocco | D2: Ascenseur complet | F2: GEARLESS | G2: 8 | H2: 5 | I2: AKİŞ | J2: ATERYA | K2: INOX | L2: AUTOMATIQUE | M2: 70 | N2: =+IF(G2<5,"MAX4",IF(G2<7,"MAX6",IF(G2<9,"MAX8","MAX10"))) -> MAX8 | P2: Version 11/12/2025
D3: Générer devis
D4: Générer facture
G5: Porte 70 prs inf 4 & 80 pour >= 5 prs | I5: Standard, Gaine > 130 x 130. >11 étages
A10: Ref | B10: Description | C10: Composante | D10: Unité | E10: Poids | F10: Prix à proposer ss stock (min) | G10: Prix à proposer (normal) | H10: Prix à proposer avec stock | I10: Quantité | S10: ARMOIRE | T10: MOTEUR | U10: PORTE | V10: OPÉRATEUR | W10: CABINE & ARCADE | X10: RAILS & ACCESSOIRES | Y10: CABLES & ACCESSOIRES | Z10: CABLES ELECTRIQUES & ACCESSOIRES | AA10: BOUTONS | AB10: GOSE | AC10: AUTRES
A11: =+'Pricing sheet'!A21 -> IT.1 | B11: =+'Pricing sheet'!B21 -> SET CABINE STANDARD INOX 1200/1100 + ARCADES & ACCESSOIRES GEARBOX | C11: =+'Pricing sheet'!C21 -> CABINE & ARCADE | D11: =+'Pricing sheet'!D21 -> SET | E11: =+'Pricing sheet'!E21 -> 650 | F11: =+'Pricing sheet'!M21 -> 25001.245 | G11: =+'Pricing sheet'!N21 -> 25736.245 | H11: =+'Pricing sheet'!O21 -> 28924.699 | S11: =IF($C11=S$10,IF(AND(ISNUMBER(SEARCH($F$2,$B11)),ISNUMBER(SEARCH($N$2,$B11)),ISNUMBER(SEARCH($N$2,$B11))),1,""),"") | T11: =IF($C11=T$10,IF(AND(ISNUMBER(SEARCH($F$2,$B11)),ISNUMBER(SEARCH($N$2,$B11)),ISNUMBER(SEARCH($I$2,$B11))),1,""),"") | U11: =IF($C11=U$10,IF(AND(ISNUMBER(SEARCH($M$2,$B11)),ISNUMBER(SEARCH($L$2,$B11)),ISNUMBER(SEARCH($J$2,$B11)),ISNUMBER(SEARCH($K$2,$B11))),$H$2,""),"") | V11: =IF($C11=V$10,IF(AND(ISNUMBER(SEARCH($M$2,$B11)),ISNUMBER(SEARCH($J$2,$B11))),1,""),"")
A12: =+'Pricing sheet'!A22 -> IT.1-1 | B12: =+'Pricing sheet'!B22 -> CABINE INOX 1000/900 STANDARD | C12: =+'Pricing sheet'!C22 -> CABINE & ARCADE | D12: =+'Pricing sheet'!D22 -> Pc | E12: =+'Pricing sheet'!E22 -> 350 | F12: =+'Pricing sheet'!M22 -> 15332.112 | G12: =+'Pricing sheet'!N22 -> 15797.612 | H12: =+'Pricing sheet'!O22 -> 17814.458 | S12: =IF($C12=S$10,IF(AND(ISNUMBER(SEARCH($F$2,$B12)),ISNUMBER(SEARCH($N$2,$B12)),ISNUMBER(SEARCH($N$2,$B12))),1,""),"") | T12: =IF($C12=T$10,IF(AND(ISNUMBER(SEARCH($F$2,$B12)),ISNUMBER(SEARCH($N$2,$B12)),ISNUMBER(SEARCH($I$2,$B12))),1,""),"") | U12: =IF($C12=U$10,IF(AND(ISNUMBER(SEARCH($M$2,$B12)),ISNUMBER(SEARCH($L$2,$B12)),ISNUMBER(SEARCH($J$2,$B12)),ISNUMBER(SEARCH($K$2,$B12))),$H$2,""),"") | V12: =IF($C12=V$10,IF(AND(ISNUMBER(SEARCH($M$2,$B12)),ISNUMBER(SEARCH($J$2,$B12))),1,""),"")
A13: =+'Pricing sheet'!A23 -> IT.1-2 | B13: =+'Pricing sheet'!B23 -> CABINE INOX 1000/900 PERSONALISÉE | C13: =+'Pricing sheet'!C23 -> CABINE & ARCADE | D13: =+'Pricing sheet'!D23 -> Pc | E13: =+'Pricing sheet'!E23 -> 350 | F13: =+'Pricing sheet'!M23 -> 18622.267 | G13: =+'Pricing sheet'!N23 -> 19210.267 | H13: =+'Pricing sheet'!O23 -> 21759.302 | S13: =IF($C13=S$10,IF(AND(ISNUMBER(SEARCH($F$2,$B13)),ISNUMBER(SEARCH($N$2,$B13)),ISNUMBER(SEARCH($N$2,$B13))),1,""),"") | T13: =IF($C13=T$10,IF(AND(ISNUMBER(SEARCH($F$2,$B13)),ISNUMBER(SEARCH($N$2,$B13)),ISNUMBER(SEARCH($I$2,$B13))),1,""),"") | U13: =IF($C13=U$10,IF(AND(ISNUMBER(SEARCH($M$2,$B13)),ISNUMBER(SEARCH($L$2,$B13)),ISNUMBER(SEARCH($J$2,$B13)),ISNUMBER(SEARCH($K$2,$B13))),$H$2,""),"") | V13: =IF($C13=V$10,IF(AND(ISNUMBER(SEARCH($M$2,$B13)),ISNUMBER(SEARCH($J$2,$B13))),1,""),"")
A14: =+'Pricing sheet'!A24 -> IT.1-3 | B14: =+'Pricing sheet'!B24 -> CABINE INOX 1100/1000 STANDARD | C14: =+'Pricing sheet'!C24 -> CABINE & ARCADE | D14: =+'Pricing sheet'!D24 -> Pc | E14: =+'Pricing sheet'!E24 -> 350 | F14: =+'Pricing sheet'!M24 -> 16253.295 | G14: =+'Pricing sheet'!N24 -> 16753.095 | H14: =+'Pricing sheet'!O24 -> 18918.893 | S14: =IF($C14=S$10,IF(AND(ISNUMBER(SEARCH($F$2,$B14)),ISNUMBER(SEARCH($N$2,$B14)),ISNUMBER(SEARCH($N$2,$B14))),1,""),"") | T14: =IF($C14=T$10,IF(AND(ISNUMBER(SEARCH($F$2,$B14)),ISNUMBER(SEARCH($N$2,$B14)),ISNUMBER(SEARCH($I$2,$B14))),1,""),"") | U14: =IF($C14=U$10,IF(AND(ISNUMBER(SEARCH($M$2,$B14)),ISNUMBER(SEARCH($L$2,$B14)),ISNUMBER(SEARCH($J$2,$B14)),ISNUMBER(SEARCH($K$2,$B14))),$H$2,""),"") | V14: =IF($C14=V$10,IF(AND(ISNUMBER(SEARCH($M$2,$B14)),ISNUMBER(SEARCH($J$2,$B14))),1,""),"")
A15: =+'Pricing sheet'!A25 -> IT.1-4 | B15: =+'Pricing sheet'!B25 -> CABINE INOX 1100/1000 PERSONALISÉE | C15: =+'Pricing sheet'!C25 -> CABINE & ARCADE | D15: =+'Pricing sheet'!D25 -> Pc | E15: =+'Pricing sheet'!E25 -> 350 | F15: =+'Pricing sheet'!M25 -> 20201.754 | G15: =+'Pricing sheet'!N25 -> 20848.554 | H15: =+'Pricing sheet'!O25 -> 23653.253 | S15: =IF($C15=S$10,IF(AND(ISNUMBER(SEARCH($F$2,$B15)),ISNUMBER(SEARCH($N$2,$B15)),ISNUMBER(SEARCH($N$2,$B15))),1,""),"") | T15: =IF($C15=T$10,IF(AND(ISNUMBER(SEARCH($F$2,$B15)),ISNUMBER(SEARCH($N$2,$B15)),ISNUMBER(SEARCH($I$2,$B15))),1,""),"") | U15: =IF($C15=U$10,IF(AND(ISNUMBER(SEARCH($M$2,$B15)),ISNUMBER(SEARCH($L$2,$B15)),ISNUMBER(SEARCH($J$2,$B15)),ISNUMBER(SEARCH($K$2,$B15))),$H$2,""),"") | V15: =IF($C15=V$10,IF(AND(ISNUMBER(SEARCH($M$2,$B15)),ISNUMBER(SEARCH($J$2,$B15))),1,""),"")
A16: =+'Pricing sheet'!A26 -> IT.1-5 | B16: =+'Pricing sheet'!B26 -> CABINE INOX 1200/1100 STANDARD | C16: =+'Pricing sheet'!C26 -> CABINE & ARCADE | D16: =+'Pricing sheet'!D26 -> Pc | E16: =+'Pricing sheet'!E26 -> 350 | F16: =+'Pricing sheet'!M26 -> 17174.525 | G16: =+'Pricing sheet'!N26 -> 17708.625 | H16: =+'Pricing sheet'!O26 -> 20023.423 | S16: =IF($C16=S$10,IF(AND(ISNUMBER(SEARCH($F$2,$B16)),ISNUMBER(SEARCH($N$2,$B16)),ISNUMBER(SEARCH($N$2,$B16))),1,""),"") | T16: =IF($C16=T$10,IF(AND(ISNUMBER(SEARCH($F$2,$B16)),ISNUMBER(SEARCH($N$2,$B16)),ISNUMBER(SEARCH($I$2,$B16))),1,""),"") | U16: =IF($C16=U$10,IF(AND(ISNUMBER(SEARCH($M$2,$B16)),ISNUMBER(SEARCH($L$2,$B16)),ISNUMBER(SEARCH($J$2,$B16)),ISNUMBER(SEARCH($K$2,$B16))),$H$2,""),"") | V16: =IF($C16=V$10,IF(AND(ISNUMBER(SEARCH($M$2,$B16)),ISNUMBER(SEARCH($J$2,$B16))),1,""),"")
A17: =+'Pricing sheet'!A27 -> IT.1-6 | B17: =+'Pricing sheet'!B27 -> CABINE INOX 1200/1100 PERSONALISÉE | C17: =+'Pricing sheet'!C27 -> CABINE & ARCADE | D17: =+'Pricing sheet'!D27 -> Pc | E17: =+'Pricing sheet'!E27 -> 350 | F17: =+'Pricing sheet'!M27 -> 21123.186 | G17: =+'Pricing sheet'!N27 -> 21804.286 | H17: =+'Pricing sheet'!O27 -> 24758.186 | S17: =IF($C17=S$10,IF(AND(ISNUMBER(SEARCH($F$2,$B17)),ISNUMBER(SEARCH($N$2,$B17)),ISNUMBER(SEARCH($N$2,$B17))),1,""),"") | T17: =IF($C17=T$10,IF(AND(ISNUMBER(SEARCH($F$2,$B17)),ISNUMBER(SEARCH($N$2,$B17)),ISNUMBER(SEARCH($I$2,$B17))),1,""),"") | U17: =IF($C17=U$10,IF(AND(ISNUMBER(SEARCH($M$2,$B17)),ISNUMBER(SEARCH($L$2,$B17)),ISNUMBER(SEARCH($J$2,$B17)),ISNUMBER(SEARCH($K$2,$B17))),$H$2,""),"") | V17: =IF($C17=V$10,IF(AND(ISNUMBER(SEARCH($M$2,$B17)),ISNUMBER(SEARCH($J$2,$B17))),1,""),"")
A18: =+'Pricing sheet'!A28 -> IT.1-13 | B18: =+'Pricing sheet'!B28 -> CABINE INOX 1400/1300 STANDARD | C18: =+'Pricing sheet'!C28 -> CABINE & ARCADE | D18: =+'Pricing sheet'!D28 -> SET | E18: =+'Pricing sheet'!E28 -> 350 | F18: =+'Pricing sheet'!M28 -> 20289.246 | G18: =+'Pricing sheet'!N28 -> 20945.846 | H18: =+'Pricing sheet'!O28 -> 23793.169 | S18: =IF($C18=S$10,IF(AND(ISNUMBER(SEARCH($F$2,$B18)),ISNUMBER(SEARCH($N$2,$B18)),ISNUMBER(SEARCH($N$2,$B18))),1,""),"") | T18: =IF($C18=T$10,IF(AND(ISNUMBER(SEARCH($F$2,$B18)),ISNUMBER(SEARCH($N$2,$B18)),ISNUMBER(SEARCH($I$2,$B18))),1,""),"") | U18: =IF($C18=U$10,IF(AND(ISNUMBER(SEARCH($M$2,$B18)),ISNUMBER(SEARCH($L$2,$B18)),ISNUMBER(SEARCH($J$2,$B18)),ISNUMBER(SEARCH($K$2,$B18))),$H$2,""),"") | V18: =IF($C18=V$10,IF(AND(ISNUMBER(SEARCH($M$2,$B18)),ISNUMBER(SEARCH($J$2,$B18))),1,""),"")
A19: =+'Pricing sheet'!A29 -> IT.1-14 | B19: =+'Pricing sheet'!B29 -> CABINE INOX 1400/1300 PERSONALISÉE | C19: =+'Pricing sheet'!C29 -> CABINE & ARCADE | D19: =+'Pricing sheet'!D29 -> SET | E19: =+'Pricing sheet'!E29 -> 350 | F19: =+'Pricing sheet'!M29 -> 26349.079 | G19: =+'Pricing sheet'!N29 -> 27201.679 | H19: =+'Pricing sheet'!O29 -> 30902.291 | S19: =IF($C19=S$10,IF(AND(ISNUMBER(SEARCH($F$2,$B19)),ISNUMBER(SEARCH($N$2,$B19)),ISNUMBER(SEARCH($N$2,$B19))),1,""),"") | T19: =IF($C19=T$10,IF(AND(ISNUMBER(SEARCH($F$2,$B19)),ISNUMBER(SEARCH($N$2,$B19)),ISNUMBER(SEARCH($I$2,$B19))),1,""),"") | U19: =IF($C19=U$10,IF(AND(ISNUMBER(SEARCH($M$2,$B19)),ISNUMBER(SEARCH($L$2,$B19)),ISNUMBER(SEARCH($J$2,$B19)),ISNUMBER(SEARCH($K$2,$B19))),$H$2,""),"") | V19: =IF($C19=V$10,IF(AND(ISNUMBER(SEARCH($M$2,$B19)),ISNUMBER(SEARCH($J$2,$B19))),1,""),"")
A20: =+'Pricing sheet'!A30 -> IT.1-17 | B20: =+'Pricing sheet'!B30 -> CABINE 1000/900 PANORAMIQUE | C20: =+'Pricing sheet'!C30 -> CABINE & ARCADE | D20: =+'Pricing sheet'!D30 -> Pc | E20: =+'Pricing sheet'!E30 -> 350 | F20: =+'Pricing sheet'!M30 -> 24227.962 | G20: =+'Pricing sheet'!N30 -> 25011.962 | H20: =+'Pricing sheet'!O30 -> 28413.749 | S20: =IF($C20=S$10,IF(AND(ISNUMBER(SEARCH($F$2,$B20)),ISNUMBER(SEARCH($N$2,$B20)),ISNUMBER(SEARCH($N$2,$B20))),1,""),"") | T20: =IF($C20=T$10,IF(AND(ISNUMBER(SEARCH($F$2,$B20)),ISNUMBER(SEARCH($N$2,$B20)),ISNUMBER(SEARCH($I$2,$B20))),1,""),"") | U20: =IF($C20=U$10,IF(AND(ISNUMBER(SEARCH($M$2,$B20)),ISNUMBER(SEARCH($L$2,$B20)),ISNUMBER(SEARCH($J$2,$B20)),ISNUMBER(SEARCH($K$2,$B20))),$H$2,""),"") | V20: =IF($C20=V$10,IF(AND(ISNUMBER(SEARCH($M$2,$B20)),ISNUMBER(SEARCH($J$2,$B20))),1,""),"")
A21: =+'Pricing sheet'!A31 -> IT.1-18 | B21: =+'Pricing sheet'!B31 -> CABINE 1100/1000 PANORAMIQUE | C21: =+'Pricing sheet'!C31 -> CABINE & ARCADE | D21: =+'Pricing sheet'!D31 -> Pc | E21: =+'Pricing sheet'!E31 -> 350 | F21: =+'Pricing sheet'!M31 -> 25743.026 | G21: =+'Pricing sheet'!N31 -> 26576.026 | H21: =+'Pricing sheet'!O31 -> 30191.241 | S21: =IF($C21=S$10,IF(AND(ISNUMBER(SEARCH($F$2,$B21)),ISNUMBER(SEARCH($N$2,$B21)),ISNUMBER(SEARCH($N$2,$B21))),1,""),"") | T21: =IF($C21=T$10,IF(AND(ISNUMBER(SEARCH($F$2,$B21)),ISNUMBER(SEARCH($N$2,$B21)),ISNUMBER(SEARCH($I$2,$B21))),1,""),"") | U21: =IF($C21=U$10,IF(AND(ISNUMBER(SEARCH($M$2,$B21)),ISNUMBER(SEARCH($L$2,$B21)),ISNUMBER(SEARCH($J$2,$B21)),ISNUMBER(SEARCH($K$2,$B21))),$H$2,""),"") | V21: =IF($C21=V$10,IF(AND(ISNUMBER(SEARCH($M$2,$B21)),ISNUMBER(SEARCH($J$2,$B21))),1,""),"")
A22: =+'Pricing sheet'!A32 -> IT.1-19 | B22: =+'Pricing sheet'!B32 -> CABINE 1200/1100 PANORAMIQUE | C22: =+'Pricing sheet'!C32 -> CABINE & ARCADE | D22: =+'Pricing sheet'!D32 -> Pc | E22: =+'Pricing sheet'!E32 -> 350 | F22: =+'Pricing sheet'!M32 -> 28015.803 | G22: =+'Pricing sheet'!N32 -> 28922.303 | H22: =+'Pricing sheet'!O32 -> 32857.839 | S22: =IF($C22=S$10,IF(AND(ISNUMBER(SEARCH($F$2,$B22)),ISNUMBER(SEARCH($N$2,$B22)),ISNUMBER(SEARCH($N$2,$B22))),1,""),"") | T22: =IF($C22=T$10,IF(AND(ISNUMBER(SEARCH($F$2,$B22)),ISNUMBER(SEARCH($N$2,$B22)),ISNUMBER(SEARCH($I$2,$B22))),1,""),"") | U22: =IF($C22=U$10,IF(AND(ISNUMBER(SEARCH($M$2,$B22)),ISNUMBER(SEARCH($L$2,$B22)),ISNUMBER(SEARCH($J$2,$B22)),ISNUMBER(SEARCH($K$2,$B22))),$H$2,""),"") | V22: =IF($C22=V$10,IF(AND(ISNUMBER(SEARCH($M$2,$B22)),ISNUMBER(SEARCH($J$2,$B22))),1,""),"")
A23: =+'Pricing sheet'!A33 -> IT.1-20 | B23: =+'Pricing sheet'!B33 -> CABINE INOX 1300/1200 STANDARD | C23: =+'Pricing sheet'!C33 -> CABINE & ARCADE | D23: =+'Pricing sheet'!D33 -> Pc | E23: =+'Pricing sheet'!E33 -> 350 | F23: =+'Pricing sheet'!M33 -> 18095.802 | G23: =+'Pricing sheet'!N33 -> 18664.202 | H23: =+'Pricing sheet'!O33 -> 21128.046 | S23: =IF($C23=S$10,IF(AND(ISNUMBER(SEARCH($F$2,$B23)),ISNUMBER(SEARCH($N$2,$B23)),ISNUMBER(SEARCH($N$2,$B23))),1,""),"") | T23: =IF($C23=T$10,IF(AND(ISNUMBER(SEARCH($F$2,$B23)),ISNUMBER(SEARCH($N$2,$B23)),ISNUMBER(SEARCH($I$2,$B23))),1,""),"") | U23: =IF($C23=U$10,IF(AND(ISNUMBER(SEARCH($M$2,$B23)),ISNUMBER(SEARCH($L$2,$B23)),ISNUMBER(SEARCH($J$2,$B23)),ISNUMBER(SEARCH($K$2,$B23))),$H$2,""),"") | V23: =IF($C23=V$10,IF(AND(ISNUMBER(SEARCH($M$2,$B23)),ISNUMBER(SEARCH($J$2,$B23))),1,""),"")
A24: =+'Pricing sheet'!A34 -> IT.1-21 | B24: =+'Pricing sheet'!B34 -> CABINE INOX 1300/1200 PERSONALISÉE | C24: =+'Pricing sheet'!C34 -> CABINE & ARCADE | D24: =+'Pricing sheet'!D34 -> Pc | E24: =+'Pricing sheet'!E34 -> 350 | F24: =+'Pricing sheet'!M34 -> 22107.034 | G24: =+'Pricing sheet'!N34 -> 22822.434 | H24: =+'Pricing sheet'!O34 -> 25925.583 | I24: =IF(SUM(S24:AC24)<>0,SUM(S24:AC24),"") | S24: =IF($C24=S$10,IF(AND(ISNUMBER(SEARCH($F$2,$B24)),ISNUMBER(SEARCH($N$2,$B24)),ISNUMBER(SEARCH($N$2,$B24))),1,""),"") | T24: =IF($C24=T$10,IF(AND(ISNUMBER(SEARCH($F$2,$B24)),ISNUMBER(SEARCH($N$2,$B24)),ISNUMBER(SEARCH($I$2,$B24))),1,""),"") | U24: =IF($C24=U$10,IF(AND(ISNUMBER(SEARCH($M$2,$B24)),ISNUMBER(SEARCH($L$2,$B24)),ISNUMBER(SEARCH($J$2,$B24)),ISNUMBER(SEARCH($K$2,$B24))),$H$2,""),"") | V24: =IF($C24=V$10,IF(AND(ISNUMBER(SEARCH($M$2,$B24)),ISNUMBER(SEARCH($J$2,$B24))),1,""),"")
A25: =+'Pricing sheet'!A35 -> IT.1-22 | B25: =+'Pricing sheet'!B35 -> CABINE 1300/1200 PANORAMIQUE | C25: =+'Pricing sheet'!C35 -> CABINE & ARCADE | D25: =+'Pricing sheet'!D35 -> Pc | E25: =+'Pricing sheet'!E35 -> 350 | F25: =+'Pricing sheet'!M35 -> 31046.507 | G25: =+'Pricing sheet'!N35 -> 32051.007 | H25: =+'Pricing sheet'!O35 -> 36413.975 | I25: =IF(SUM(S25:AC25)<>0,SUM(S25:AC25),"") | S25: =IF($C25=S$10,IF(AND(ISNUMBER(SEARCH($F$2,$B25)),ISNUMBER(SEARCH($N$2,$B25)),ISNUMBER(SEARCH($N$2,$B25))),1,""),"") | T25: =IF($C25=T$10,IF(AND(ISNUMBER(SEARCH($F$2,$B25)),ISNUMBER(SEARCH($N$2,$B25)),ISNUMBER(SEARCH($I$2,$B25))),1,""),"") | U25: =IF($C25=U$10,IF(AND(ISNUMBER(SEARCH($M$2,$B25)),ISNUMBER(SEARCH($L$2,$B25)),ISNUMBER(SEARCH($J$2,$B25)),ISNUMBER(SEARCH($K$2,$B25))),$H$2,""),"") | V25: =IF($C25=V$10,IF(AND(ISNUMBER(SEARCH($M$2,$B25)),ISNUMBER(SEARCH($J$2,$B25))),1,""),"")
A26: =+'Pricing sheet'!A36 -> IT.1-23 | B26: =+'Pricing sheet'!B36 -> CABINE 1400/1300 PANORAMIQUE | C26: =+'Pricing sheet'!C36 -> CABINE & ARCADE | D26: =+'Pricing sheet'!D36 -> Pc | E26: =+'Pricing sheet'!E36 -> 350 | F26: =+'Pricing sheet'!M36 -> 34835.427 | G26: =+'Pricing sheet'!N36 -> 35962.427 | H26: =+'Pricing sheet'!O36 -> 40860.226 | I26: =IF(SUM(S26:AC26)<>0,SUM(S26:AC26),"") | S26: =IF($C26=S$10,IF(AND(ISNUMBER(SEARCH($F$2,$B26)),ISNUMBER(SEARCH($N$2,$B26)),ISNUMBER(SEARCH($N$2,$B26))),1,""),"") | T26: =IF($C26=T$10,IF(AND(ISNUMBER(SEARCH($F$2,$B26)),ISNUMBER(SEARCH($N$2,$B26)),ISNUMBER(SEARCH($I$2,$B26))),1,""),"") | U26: =IF($C26=U$10,IF(AND(ISNUMBER(SEARCH($M$2,$B26)),ISNUMBER(SEARCH($L$2,$B26)),ISNUMBER(SEARCH($J$2,$B26)),ISNUMBER(SEARCH($K$2,$B26))),$H$2,""),"") | V26: =IF($C26=V$10,IF(AND(ISNUMBER(SEARCH($M$2,$B26)),ISNUMBER(SEARCH($J$2,$B26))),1,""),"")
A27: =+'Pricing sheet'!A37 -> IT.1-7 | B27: =+'Pricing sheet'!B37 -> ARCADE CABINE 1000/900 + ARCADE CONTRE-POIDS + TIRANDS + COULISSEAUX GEARBOX | C27: =+'Pricing sheet'!C37 -> CABINE & ARCADE | D27: =+'Pricing sheet'!D37 -> SET | E27: =+'Pricing sheet'!E37 -> 200 | F27: =+'Pricing sheet'!M37 -> 6811.6294 | G27: =+'Pricing sheet'!N37 -> 7252.6294 | H27: =+'Pricing sheet'!O37 -> 7986.3968 | I27: =IF(SUM(S27:AC27)<>0,SUM(S27:AC27),"") | S27: =IF($C27=S$10,IF(AND(ISNUMBER(SEARCH($F$2,$B27)),ISNUMBER(SEARCH($N$2,$B27)),ISNUMBER(SEARCH($N$2,$B27))),1,""),"") | T27: =IF($C27=T$10,IF(AND(ISNUMBER(SEARCH($F$2,$B27)),ISNUMBER(SEARCH($N$2,$B27)),ISNUMBER(SEARCH($I$2,$B27))),1,""),"") | U27: =IF($C27=U$10,IF(AND(ISNUMBER(SEARCH($M$2,$B27)),ISNUMBER(SEARCH($L$2,$B27)),ISNUMBER(SEARCH($J$2,$B27)),ISNUMBER(SEARCH($K$2,$B27))),$H$2,""),"") | V27: =IF($C27=V$10,IF(AND(ISNUMBER(SEARCH($M$2,$B27)),ISNUMBER(SEARCH($J$2,$B27))),1,""),"")
A28: =+'Pricing sheet'!A38 -> IT.1-8 | B28: =+'Pricing sheet'!B38 -> ARCADE CABINE 1000/900 + ARCADE CONTRE-POIDS + TIRANDS + COULISSEAUX GEARLESS | C28: =+'Pricing sheet'!C38 -> CABINE & ARCADE | D28: =+'Pricing sheet'!D38 -> SET | E28: =+'Pricing sheet'!E38 -> 200 | F28: =+'Pricing sheet'!M38 -> 10596.708 | G28: =+'Pricing sheet'!N38 -> 11282.708 | H28: =+'Pricing sheet'!O38 -> 12424.965 | I28: =IF(SUM(S28:AC28)<>0,SUM(S28:AC28),"") | S28: =IF($C28=S$10,IF(AND(ISNUMBER(SEARCH($F$2,$B28)),ISNUMBER(SEARCH($N$2,$B28)),ISNUMBER(SEARCH($N$2,$B28))),1,""),"") | T28: =IF($C28=T$10,IF(AND(ISNUMBER(SEARCH($F$2,$B28)),ISNUMBER(SEARCH($N$2,$B28)),ISNUMBER(SEARCH($I$2,$B28))),1,""),"") | U28: =IF($C28=U$10,IF(AND(ISNUMBER(SEARCH($M$2,$B28)),ISNUMBER(SEARCH($L$2,$B28)),ISNUMBER(SEARCH($J$2,$B28)),ISNUMBER(SEARCH($K$2,$B28))),$H$2,""),"") | V28: =IF($C28=V$10,IF(AND(ISNUMBER(SEARCH($M$2,$B28)),ISNUMBER(SEARCH($J$2,$B28))),1,""),"")
A29: =+'Pricing sheet'!A39 -> IT.1-9 | B29: =+'Pricing sheet'!B39 -> ARCADE CABINE 1100/1000 + ARCADE CONTRE-POIDS + TIRANDS + COULISSEAUX GEARBOX | C29: =+'Pricing sheet'!C39 -> CABINE & ARCADE | D29: =+'Pricing sheet'!D39 -> SET | E29: =+'Pricing sheet'!E39 -> 200 | F29: =+'Pricing sheet'!M39 -> 7114.4136 | G29: =+'Pricing sheet'!N39 -> 7575.0136 | H29: =+'Pricing sheet'!O39 -> 8341.4381 | I29: =IF(SUM(S29:AC29)<>0,SUM(S29:AC29),"") | S29: =IF($C29=S$10,IF(AND(ISNUMBER(SEARCH($F$2,$B29)),ISNUMBER(SEARCH($N$2,$B29)),ISNUMBER(SEARCH($N$2,$B29))),1,""),"") | T29: =IF($C29=T$10,IF(AND(ISNUMBER(SEARCH($F$2,$B29)),ISNUMBER(SEARCH($N$2,$B29)),ISNUMBER(SEARCH($I$2,$B29))),1,""),"") | U29: =IF($C29=U$10,IF(AND(ISNUMBER(SEARCH($M$2,$B29)),ISNUMBER(SEARCH($L$2,$B29)),ISNUMBER(SEARCH($J$2,$B29)),ISNUMBER(SEARCH($K$2,$B29))),$H$2,""),"") | V29: =IF($C29=V$10,IF(AND(ISNUMBER(SEARCH($M$2,$B29)),ISNUMBER(SEARCH($J$2,$B29))),1,""),"") | AC29: =IF(L2="SEMI",1,"")
A30: =+'Pricing sheet'!A40 -> IT.1-10 | B30: =+'Pricing sheet'!B40 -> ARCADE CABINE 1100/1000 + ARCADE CONTRE-POIDS + TIRANDS + COULISSEAUX GEARLESS | C30: =+'Pricing sheet'!C40 -> CABINE & ARCADE | D30: =+'Pricing sheet'!D40 -> SET | E30: =+'Pricing sheet'!E40 -> 200 | F30: =+'Pricing sheet'!M40 -> 10899.541 | G30: =+'Pricing sheet'!N40 -> 11605.141 | H30: =+'Pricing sheet'!O40 -> 12780.102 | I30: =IF(SUM(S30:AC30)<>0,SUM(S30:AC30),"") | S30: =IF($C30=S$10,IF(AND(ISNUMBER(SEARCH($F$2,$B30)),ISNUMBER(SEARCH($N$2,$B30)),ISNUMBER(SEARCH($N$2,$B30))),1,""),"") | T30: =IF($C30=T$10,IF(AND(ISNUMBER(SEARCH($F$2,$B30)),ISNUMBER(SEARCH($N$2,$B30)),ISNUMBER(SEARCH($I$2,$B30))),1,""),"") | U30: =IF($C30=U$10,IF(AND(ISNUMBER(SEARCH($M$2,$B30)),ISNUMBER(SEARCH($L$2,$B30)),ISNUMBER(SEARCH($J$2,$B30)),ISNUMBER(SEARCH($K$2,$B30))),$H$2,""),"") | V30: =IF($C30=V$10,IF(AND(ISNUMBER(SEARCH($M$2,$B30)),ISNUMBER(SEARCH($J$2,$B30))),1,""),"") | AC30: =IF(L3="SEMI",1,"")
A31: =+'Pricing sheet'!A41 -> IT.1-11 | B31: =+'Pricing sheet'!B41 -> ARCADE CABINE 1200/1100 + ARCADE CONTRE-POIDS + TIRANDS + COULISSEAUX GEARBOX | C31: =+'Pricing sheet'!C41 -> CABINE & ARCADE | D31: =+'Pricing sheet'!D41 -> SET | E31: =+'Pricing sheet'!E41 -> 200 | F31: =+'Pricing sheet'!M41 -> 7417.2017 | G31: =+'Pricing sheet'!N41 -> 7897.4017 | H31: =+'Pricing sheet'!O41 -> 8696.487 | I31: =IF(SUM(S31:AC31)<>0,SUM(S31:AC31),"") | S31: =IF($C31=S$10,IF(AND(ISNUMBER(SEARCH($F$2,$B31)),ISNUMBER(SEARCH($N$2,$B31)),ISNUMBER(SEARCH($N$2,$B31))),1,""),"") | T31: =IF($C31=T$10,IF(AND(ISNUMBER(SEARCH($F$2,$B31)),ISNUMBER(SEARCH($N$2,$B31)),ISNUMBER(SEARCH($I$2,$B31))),1,""),"") | U31: =IF($C31=U$10,IF(AND(ISNUMBER(SEARCH($M$2,$B31)),ISNUMBER(SEARCH($L$2,$B31)),ISNUMBER(SEARCH($J$2,$B31)),ISNUMBER(SEARCH($K$2,$B31))),$H$2,""),"") | V31: =IF($C31=V$10,IF(AND(ISNUMBER(SEARCH($M$2,$B31)),ISNUMBER(SEARCH($J$2,$B31))),1,""),"") | AC31: =IF(L4="SEMI",1,"")
A32: =+'Pricing sheet'!A42 -> IT.1-12 | B32: =+'Pricing sheet'!B42 -> ARCADE CABINE 1200/1100 + ARCADE CONTRE-POIDS + TIRANDS + COULISSEAUX GEARLESS | C32: =+'Pricing sheet'!C42 -> CABINE & ARCADE | D32: =+'Pricing sheet'!D42 -> SET | E32: =+'Pricing sheet'!E42 -> 200 | F32: =+'Pricing sheet'!M42 -> 11202.377 | G32: =+'Pricing sheet'!N42 -> 11927.577 | H32: =+'Pricing sheet'!O42 -> 13135.247 | I32: =IF(SUM(S32:AC32)<>0,SUM(S32:AC32),"") | S32: =IF($C32=S$10,IF(AND(ISNUMBER(SEARCH($F$2,$B32)),ISNUMBER(SEARCH($N$2,$B32)),ISNUMBER(SEARCH($N$2,$B32))),1,""),"") | T32: =IF($C32=T$10,IF(AND(ISNUMBER(SEARCH($F$2,$B32)),ISNUMBER(SEARCH($N$2,$B32)),ISNUMBER(SEARCH($I$2,$B32))),1,""),"") | U32: =IF($C32=U$10,IF(AND(ISNUMBER(SEARCH($M$2,$B32)),ISNUMBER(SEARCH($L$2,$B32)),ISNUMBER(SEARCH($J$2,$B32)),ISNUMBER(SEARCH($K$2,$B32))),$H$2,""),"") | V32: =IF($C32=V$10,IF(AND(ISNUMBER(SEARCH($M$2,$B32)),ISNUMBER(SEARCH($J$2,$B32))),1,""),"")
A33: =+'Pricing sheet'!A43 -> IT.1-15 | B33: =+'Pricing sheet'!B43 -> ARCADE CABINE 1400/1300 + ARCADE CONTRE-POIDS + TIRANDS + COULISSEAUX GEARBOX | C33: =+'Pricing sheet'!C43 -> CABINE & ARCADE | D33: =+'Pricing sheet'!D43 -> SET | E33: =+'Pricing sheet'!E43 -> 201 | F33: =+'Pricing sheet'!M43 -> 8931.1996 | G33: =+'Pricing sheet'!N43 -> 9509.3996 | H33: =+'Pricing sheet'!O43 -> 10471.847 | I33: =IF(SUM(S33:AC33)<>0,SUM(S33:AC33),"") | S33: =IF($C33=S$10,IF(AND(ISNUMBER(SEARCH($F$2,$B33)),ISNUMBER(SEARCH($N$2,$B33)),ISNUMBER(SEARCH($N$2,$B33))),1,""),"") | T33: =IF($C33=T$10,IF(AND(ISNUMBER(SEARCH($F$2,$B33)),ISNUMBER(SEARCH($N$2,$B33)),ISNUMBER(SEARCH($I$2,$B33))),1,""),"") | U33: =IF($C33=U$10,IF(AND(ISNUMBER(SEARCH($M$2,$B33)),ISNUMBER(SEARCH($L$2,$B33)),ISNUMBER(SEARCH($J$2,$B33)),ISNUMBER(SEARCH($K$2,$B33))),$H$2,""),"") | V33: =IF($C33=V$10,IF(AND(ISNUMBER(SEARCH($M$2,$B33)),ISNUMBER(SEARCH($J$2,$B33))),1,""),"")
A34: =+'Pricing sheet'!A44 -> IT.1-16 | B34: =+'Pricing sheet'!B44 -> ARCADE CABINE 1400/1300 + ARCADE CONTRE-POIDS + TIRANDS + COULISSEAUX GEARLESS | C34: =+'Pricing sheet'!C44 -> CABINE & ARCADE | D34: =+'Pricing sheet'!D44 -> SET | E34: =+'Pricing sheet'!E44 -> 202 | F34: =+'Pricing sheet'!M44 -> 14230.949 | G34: =+'Pricing sheet'!N44 -> 15152.149 | H34: =+'Pricing sheet'!O44 -> 16687.119 | I34: =IF(SUM(S34:AC34)<>0,SUM(S34:AC34),"") | S34: =IF($C34=S$10,IF(AND(ISNUMBER(SEARCH($F$2,$B34)),ISNUMBER(SEARCH($N$2,$B34)),ISNUMBER(SEARCH($N$2,$B34))),1,""),"") | T34: =IF($C34=T$10,IF(AND(ISNUMBER(SEARCH($F$2,$B34)),ISNUMBER(SEARCH($N$2,$B34)),ISNUMBER(SEARCH($I$2,$B34))),1,""),"") | U34: =IF($C34=U$10,IF(AND(ISNUMBER(SEARCH($M$2,$B34)),ISNUMBER(SEARCH($L$2,$B34)),ISNUMBER(SEARCH($J$2,$B34)),ISNUMBER(SEARCH($K$2,$B34))),$H$2,""),"") | V34: =IF($C34=V$10,IF(AND(ISNUMBER(SEARCH($M$2,$B34)),ISNUMBER(SEARCH($J$2,$B34))),1,""),"")
A35: =+'Pricing sheet'!A45 -> IT.1-17 | B35: =+'Pricing sheet'!B45 -> SET ARCADE TYPE L VVVF 2V | C35: =+'Pricing sheet'!C45 -> CABINE & ARCADE | D35: =+'Pricing sheet'!D45 -> SET | E35: =+'Pricing sheet'!E45 -> 203 | F35: =+'Pricing sheet'!M45 -> 15139.595 | G35: =+'Pricing sheet'!N45 -> 16119.595 | H35: =+'Pricing sheet'!O45 -> 17752.831 | I35: =IF(SUM(S35:AC35)<>0,SUM(S35:AC35),"") | S35: =IF($C35=S$10,IF(AND(ISNUMBER(SEARCH($F$2,$B35)),ISNUMBER(SEARCH($N$2,$B35)),ISNUMBER(SEARCH($N$2,$B35))),1,""),"") | T35: =IF($C35=T$10,IF(AND(ISNUMBER(SEARCH($F$2,$B35)),ISNUMBER(SEARCH($N$2,$B35)),ISNUMBER(SEARCH($I$2,$B35))),1,""),"") | U35: =IF($C35=U$10,IF(AND(ISNUMBER(SEARCH($M$2,$B35)),ISNUMBER(SEARCH($L$2,$B35)),ISNUMBER(SEARCH($J$2,$B35)),ISNUMBER(SEARCH($K$2,$B35))),$H$2,""),"") | V35: =IF($C35=V$10,IF(AND(ISNUMBER(SEARCH($M$2,$B35)),ISNUMBER(SEARCH($J$2,$B35))),1,""),"")
A36: =+'Pricing sheet'!A46 -> IT.1-18 | B36: =+'Pricing sheet'!B46 -> SET ARCADE TYPE L GEARLESS | C36: =+'Pricing sheet'!C46 -> CABINE & ARCADE | D36: =+'Pricing sheet'!D46 -> SET | E36: =+'Pricing sheet'!E46 -> 204 | F36: =+'Pricing sheet'!M46 -> 18168.667 | G36: =+'Pricing sheet'!N46 -> 19344.667 | H36: =+'Pricing sheet'!O46 -> 21305.702 | I36: =IF(SUM(S36:AC36)<>0,SUM(S36:AC36),"") -> 36 | S36: =IF($C36=S$10,IF(AND(ISNUMBER(SEARCH($F$2,$B36)),ISNUMBER(SEARCH($N$2,$B36)),ISNUMBER(SEARCH($N$2,$B36))),1,""),"") | T36: =IF($C36=T$10,IF(AND(ISNUMBER(SEARCH($F$2,$B36)),ISNUMBER(SEARCH($N$2,$B36)),ISNUMBER(SEARCH($I$2,$B36))),1,""),"") | U36: =IF($C36=U$10,IF(AND(ISNUMBER(SEARCH($M$2,$B36)),ISNUMBER(SEARCH($L$2,$B36)),ISNUMBER(SEARCH($J$2,$B36)),ISNUMBER(SEARCH($K$2,$B36))),$H$2,""),"") | V36: =IF($C36=V$10,IF(AND(ISNUMBER(SEARCH($M$2,$B36)),ISNUMBER(SEARCH($J$2,$B36))),1,""),"") | X36: =(INT((H2+1)*3/2))*4 -> 36
A37: =+'Pricing sheet'!A47 -> HYD1-1 | B37: =+'Pricing sheet'!B47 -> SET SYSTÈME HYDRAULIQUE MAX4 STANDARD 0,15M/S 10M COURSE (4 NIVEAUX) | C37: =+'Pricing sheet'!C47 -> HYDRAULIQUE | D37: =+'Pricing sheet'!D47 -> SET | E37: =+'Pricing sheet'!E47 -> 200 | F37: =+'Pricing sheet'!M47 -> 22712.995 | G37: =+'Pricing sheet'!N47 -> 24182.995 | H37: =+'Pricing sheet'!O47 -> 26636.449 | I37: =IF(SUM(S37:AC37)<>0,SUM(S37:AC37),"") -> 36 | S37: =IF($C37=S$10,IF(AND(ISNUMBER(SEARCH($F$2,$B37)),ISNUMBER(SEARCH($N$2,$B37)),ISNUMBER(SEARCH($N$2,$B37))),1,""),"") | T37: =IF($C37=T$10,IF(AND(ISNUMBER(SEARCH($F$2,$B37)),ISNUMBER(SEARCH($N$2,$B37)),ISNUMBER(SEARCH($I$2,$B37))),1,""),"") | U37: =IF($C37=U$10,IF(AND(ISNUMBER(SEARCH($M$2,$B37)),ISNUMBER(SEARCH($L$2,$B37)),ISNUMBER(SEARCH($J$2,$B37)),ISNUMBER(SEARCH($K$2,$B37))),$H$2,""),"") | V37: =IF($C37=V$10,IF(AND(ISNUMBER(SEARCH($M$2,$B37)),ISNUMBER(SEARCH($J$2,$B37))),1,""),"") | X37: =(INT((H2+1)*3/2))*4 -> 36
A38: =+'Pricing sheet'!A48 -> HYD1-2 | B38: =+'Pricing sheet'!B48 -> SET SYSTÈME HYDRAULIQUE MAX4 STANDARD 0,15M/S 7M COURSE (3 NIVEAUX) | C38: =+'Pricing sheet'!C48 -> HYDRAULIQUE | D38: =+'Pricing sheet'!D48 -> SET | E38: =+'Pricing sheet'!E48 -> 198 | F38: =+'Pricing sheet'!M48 -> 521.235 | G38: =+'Pricing sheet'!N48 -> 521.235 | H38: =+'Pricing sheet'!O48 -> 521.235 | I38: =IF(SUM(S38:AC38)<>0,SUM(S38:AC38),"") -> 36 | S38: =IF($C38=S$10,IF(AND(ISNUMBER(SEARCH($F$2,$B38)),ISNUMBER(SEARCH($N$2,$B38)),ISNUMBER(SEARCH($N$2,$B38))),1,""),"") | T38: =IF($C38=T$10,IF(AND(ISNUMBER(SEARCH($F$2,$B38)),ISNUMBER(SEARCH($N$2,$B38)),ISNUMBER(SEARCH($I$2,$B38))),1,""),"") | U38: =IF($C38=U$10,IF(AND(ISNUMBER(SEARCH($M$2,$B38)),ISNUMBER(SEARCH($L$2,$B38)),ISNUMBER(SEARCH($J$2,$B38)),ISNUMBER(SEARCH($K$2,$B38))),$H$2,""),"") | V38: =IF($C38=V$10,IF(AND(ISNUMBER(SEARCH($M$2,$B38)),ISNUMBER(SEARCH($J$2,$B38))),1,""),"") | X38: =+X36 -> 36
